Workbook

Sheet 使い方
A1: Bistro Knocks 原価管理シート
A2: Cost Master — 業者単価を入れるだけで全メニューの原価率／利益率が自動算出
A4: 凡例
B5: 入力欄 | C5: 業者単価などを手入力（薄アイボリー）
B6: 自動計算 | C6: 関数で算出（白）
B7: 合計／重要 | C7: 合計原価などの重要セル（淡ゴールド）
A10: 【税の前提】
A11: ・販売価格は税込で運用、業者からの単価は税抜で入る前提です。
A12: ・原価率・利益率は飲食業の慣行に合わせ「税抜ベース」で算出します。
A13: ・販売価格（税抜）= 販売価格（税込）÷ 1.08（軽減税率 / テイクアウト弁当）。
A14: ・各マスタの単価入力欄は全て『税抜』で入力してください。
A15: ・食材の使用量は『掃除前重量』（業者単価と同じベース）で記載。歩留まりは別途反映しません。
A17: 【使い方】
A18: 1. 業者から単価が届いたら、以下の薄黄色セルに入力してください：
A19: ・食材マスタ シート C列＝仕入単価（税込）、D列＝仕入単位量（例: 100g単位なら 100）
A20: →E列「税込/単位」と F列「税抜/単位」が自動計算され、原価計算ではF列が使われます。
A21: ・飲料マスタ シート D列（pet_free / pet / pack の3件）
A22: ・サイドマスタ シート C列（7品目: ピクルス・ポテト・卵・ご飯・かぼちゃ・小エビ・有頭エビ）
... A47: 薄黄色＝業者単価待ちの入力セル

Sheet 食材マスタ
A1: 食材名 | B1: 使用単位 | C1: 仕入単価（税込・円） | D1: 仕入単位量 | E1: 税込単位単価（円/使用単位） | F1: 税抜単位単価（円/使用単位） | G1: 備考
A2: 150gバーグ | B2: 個 | C2: 453.6 | D2: 1 | E2: =IFERROR(C2/D2,0) | F2: =IFERROR(E2/1.08,0) | G2: 赤城牛ハンバーグ150g / 税抜420円/枚（レーベン 2026-05-01）
A3: 120gバーグ | B3: 個 | C3: 243 | D3: 1 | E3: =IFERROR(C3/D3,0) | F3: =IFERROR(E3/1.08,0) | G3: ハンバーグ120g / 税抜225円/枚（レーベン 2026-05-08/12）
A4: ハラミ | B4: g | E4: =IFERROR(C4/D4,0) | F4: =IFERROR(E4/1.08,0) | G4: 最も使用頻度が高い
A5: ロービー | B5: g | E5: =IFERROR(C5/D5,0) | F5: =IFERROR(E5/1.08,0) | G5: 複数メニューで使用
A6: ミスジ | B6: g | E6: =IFERROR(C6/D6,0) | F6: =IFERROR(E6/1.08,0) | G6: 高級メニューで使用
A7: イベリコ | B7: g | E7: =IFERROR(C7/D7,0) | F7: =IFERROR(E7/1.08,0) | G7: プレミアムメニュー
A8: 厳選和牛 | B8: g | E8: =IFERROR(C8/D8,0) | F8: =IFERROR(E8/1.08,0) | G8: 最高級メニュー
A9: 豚ヒレ | B9: g | C9: 117 | D9: 100 | E9: =IFERROR(C9/D9,0) | F9: =IFERROR(E9/1.08,0) | G9: 新弁当で使用 / 117円/100g税込・掃除前（2026-05-19入手）
A10: 豚ロース | B10: g | C10: 98 | D10: 100 | E10: =IFERROR(C10/D10,0) | F10: =IFERROR(E10/1.08,0) | G10: 新弁当で使用 / 98円/100g税込・掃除前（2026-05-19入手）
A11: とりむね | B11: g | E11: =IFERROR(C11/D11,0) | F11: =IFERROR(E11/1.08,0) | G11: 新弁当で使用
A12: 鯛 | B12: カット | E12: =IFERROR(C12/D12,0) | F12: =IFERROR(E12/1.08,0) | G12: 黒弁当・新弁当で使用
A13: サーモン | B13: カット | E13: =IFERROR(C13/D13,0) | F13: =IFERROR(E13/1.08,0) | G13: 黒弁当・新弁当で使用
A14: カジキ | B14: g | E14: =IFERROR(C14/D14,0) | F14: =IFERROR(E14/1.08,0) | G14: 新弁当で使用
A15: 赤魚 | B15: g | E15: =IFERROR(C15/D15,0) | F15: =IFERROR(E15/1.08,0) | G15: 新弁当で使用
A16: 大豆バーグ | B16: 個 | E16: =IFERROR(C16/D16,0) | F16: =IFERROR(E16/1.08,0) | G16: 低糖質弁当
A17: 豆腐 | B17: 丁 | E17: =IFERROR(C17/D17,0) | F17: =IFERROR(E17/1.08,0) | G17: 低糖質弁当

Sheet 飲料マスタ
A1: 飲料ID | B1: 飲料名 | C1: 販売価格（税込・円） | D1: 税抜原価（円） | E1: 備考
A2: none | B2: 無し | C2: 0 | D2: 0 | E2: 飲料なし
A3: pet_free | B3: PET茶（無料） | C3: 0 | E3: 2,500円以上の弁当に自動付与
A4: pet | B4: PET茶 180円 | C4: 180 | E4: 有料オプション
A5: pack | B5: 紙茶 100円 | C5: 100 | E5: 有料オプション

Sheet サイドマスタ
A1: サイド名 | B1: 単位 | C1: 黒弁当量 | D1: 新弁当量 | E1: 税抜単位単価（円/単位） | F1: 備考
A2: ピクルス | B2: g | C2: 15 | D2: 15 | E2: =IFERROR(VLOOKUP("ピクルス",ソース定義マスタ!$A:$E,5,FALSE),0) | F2: 全メニュー / 自家製レシピ(ソース定義マスタから)
A3: ポテトサラダ | B3: g | C3: 25 | D3: 25 | F3: 全メニュー / 自家製レシピ未登録
A4: 卵 | B4: 個 | C4: 1 | D4: 1 | F4: 全メニュー / 単価入力
A5: ご飯 | B5: g | C5: 160 | D5: 160 | F5: ほぼ全メニュー / 単価入力（低糖質はフラグで除外）
A6: かぼちゃ | B6: g | D6: 0 | F6: 黒弁当のみ / 単価入力
A7: 小エビ | B7: 個 | D7: 0 | F7: 黒弁当の魚系以外 / 単価入力
A8: 有頭エビ | B8: 個 | D8: 0 | F8: 魚系メニュー / 単価入力
A9: サラダベース | B9: g | C9: 35 | D9: 20 | E9: =IFERROR(VLOOKUP("サラダベース",ソース定義マスタ!$A:$E,5,FALSE),0) | F9: 全メニュー / 自家製レシピ(ソース定義マスタから)
A10: ミニトマト | B10: 個 | C10: 0.5 | D10: 0.5 | E10: =IFERROR(VLOOKUP("ミニトマト",レシピ材料マスタ!$A:$F,6,FALSE),0) | F10: 全メニュー / レシピ材料マスタから直接
A11: 蒸し野菜 | B11: g | C11: 55 | D11: 35 | F11: 全メニュー / 構成未確定（後でレシピ材料/レシピ化）
A12: ブロッコリー | B12: g | C12: 6 | D12: 6 | E12: =IFERROR(VLOOKUP("ブロッコリー(冷凍)",レシピ材料マスタ!$A:$F,6,FALSE),0) | F12: 全メニュー / ユニフーズ冷凍500g

Sheet 資材マスタ
A1: 資材名 | B1: 分類 | C1: 税抜単価（円／個） | D1: 適用
A2: 容器（黒） | B2: サイズ別 | D2: 黒弁当のみ
A3: 容器（新） | B3: サイズ別 | D3: 新弁当のみ
A4: 蓋（黒） | B4: サイズ別 | D4: 黒弁当のみ
A5: 蓋（新） | B5: サイズ別 | D5: 新弁当のみ
A6: 箸 | B6: 共通 | D6: 全メニュー
A7: ワサガード | B7: 共通 | D7: 全メニュー
A8: 帯 | B8: 共通 | D8: 全メニュー
A9: シーザードレッシング | B9: 共通 | C9: 16.15 | D9: 全メニュー / QP 1袋10ml×40袋/箱 税抜646円（トーホー 2026-05-18）
A10: おしぼり | B10: 共通 | D10: 全メニュー

Sheet レシピ材料マスタ
A1: 材料名 | B1: 単位 | C1: 仕入単価（税込・円） | D1: 仕入単位量 | E1: 税込単位単価（円/単位） | F1: 税抜単位単価（円/単位） | G1: 備考
A2: 味醂 | B2: cc | E2: =IFERROR(C2/D2,0) | F2: =IFERROR(E2/1.08,0) | G2: ソース1/6で使用
A3: 醤油 | B3: cc | E3: =IFERROR(C3/D3,0) | F3: =IFERROR(E3/1.08,0) | G3: ソース1/6で使用
A4: マギーブイヨン | B4: 個 | E4: =IFERROR(C4/D4,0) | F4: =IFERROR(E4/1.08,0) | G4: ソース1で使用
A5: 顆粒だし | B5: g | E5: =IFERROR(C5/D5,0) | F5: =IFERROR(E5/1.08,0) | G5: ソース1で使用
A6: しめじ | B6: pc | E6: =IFERROR(C6/D6,0) | F6: =IFERROR(E6/1.08,0) | G6: ソース1で使用（コンカッセ）
A7: えのき | B7: pc | E7: =IFERROR(C7/D7,0) | F7: =IFERROR(E7/1.08,0) | G7: ソース1で使用（コンカッセ）
A8: エリンギ | B8: pc | E8: =IFERROR(C8/D8,0) | F8: =IFERROR(E8/1.08,0) | G8: ソース1で使用（コンカッセ）
A9: 水 | B9: cc | C9: 0 | D9: 1 | E9: =IFERROR(C9/D9,0) | F9: =IFERROR(E9/1.08,0) | G9: ソース1で使用 ※単価0想定
A10: 粒マスタード | B10: g | E10: =IFERROR(C10/D10,0) | F10: =IFERROR(E10/1.08,0) | G10: ソース1で使用（ソース全量×5%）
A11: 白ワイン | B11: ml | E11: =IFERROR(C11/D11,0) | F11: =IFERROR(E11/1.08,0) | G11: ソース2/6で使用
A12: クラム | B12: g | E12: =IFERROR(C12/D12,0) | F12: =IFERROR(E12/1.08,0) | G12: ソース2で使用
A13: 生クリーム | B13: ml | E13: =IFERROR(C13/D13,0) | F13: =IFERROR(E13/1.08,0) | G13: ソース2で使用
A14: オニオンステーキソース | B14: cc | C14: 700.92 | D14: 1110 | E14: =IFERROR(C14/D14,0) | F14: =IFERROR(E14/1.08,0) | G14: ソース3で使用（市販） / トーホー / ステーキしょうゆ オニオン&ペッパー 1110g 税抜649円
A15: ニンニク醤油ソース | B15: cc | C15: 680.4 | D15: 1205 | E15: =IFERROR(C15/D15,0) | F15: =IFERROR(E15/1.08,0) | G15: ソース3で使用（市販） / トーホー / ステーキしょうゆ にんにく風味 1205g 税抜630円
A16: 玉ねぎ(個) | B16: 個 | E16: =IFERROR(C16/D16,0) | F16: =IFERROR(E16/1.08,0) | G16: ソース4(ピクルス)で使用
A17: 玉ねぎ(g) | B17: g | E17: =IFERROR(C17/D17,0) | F17: =IFERROR(E17/1.08,0) | G17: ソース6で使用
A18: 生姜 | B18: g | E18: =IFERROR(C18/D18,0) | F18: =IFERROR(E18/1.08,0) | G18: ソース6で使用
A19: にんにく(株) | B19: 株 | E19: =IFERROR(C19/D19,0) | F19: =IFERROR(E19/1.08,0) | G19: ソース6で使用
A20: 日本酒 | B20: cc | E20: =IFERROR(C20/D20,0) | F20: =IFERROR(E20/1.08,0) | G20: ソース6で使用
A21: 上白糖 | B21: g | E21: =IFERROR(C21/D21,0) | F21: =IFERROR(E21/1.08,0) | G21: ソース6で使用
A22: レモン | B22: 個 | E22: =IFERROR(C22/D22,0) | F22: =IFERROR(E22/1.08,0) | G22: ソース6で使用
A23: かんたん酢 | B23: ml | E23: =IFERROR(C23/D23,0) | F23: =IFERROR(E23/1.08,0) | G23: ピクルスで使用
A24: 白ワインビネガー | B24: ml | C24: 334.8 | D24: 1000 | E24: =IFERROR(C24/D24,0) | F24: =IFERROR(E24/1.08,0) | G24: ピクルスで使用 / トーホー / レストランビネガー ワインタイプ 1L 税抜310円
A25: 塩 | B25: g | E25: =IFERROR(C25/D25,0) | F25: =IFERROR(E25/1.08,0) | G25: ピクルスで使用
A26: グラニュー糖 | B26: g | E26: =IFERROR(C26/D26,0) | F26: =IFERROR(E26/1.08,0) | G26: ピクルスで使用
A27: とうがらし | B27: 本 | E27: =IFERROR(C27/D27,0) | F27: =IFERROR(E27/1.08,0) | G27: ピクルスで使用
A28: 白粒こしょう | B28: 粒 | E28: =IFERROR(C28/D28,0) | F28: =IFERROR(E28/1.08,0) | G28: ピクルスで使用
A29: 大根 | B29: 本 | E29: =IFERROR(C29/D29,0) | F29: =IFERROR(E29/1.08,0) | G29: ピクルスで使用
A30: 人参 | B30: 本 | E30: =IFERROR(C30/D30,0) | F30: =IFERROR(E30/1.08,0) | G30: ピクルスで使用
A31: パプリカ | B31: 個 | E31: =IFERROR(C31/D31,0) | F31: =IFERROR(E31/1.08,0) | G31: ピクルスで使用
A32: ヤングコーン(缶) | B32: 缶 | E32: =IFERROR(C32/D32,0) | F32: =IFERROR(E32/1.08,0) | G32: ピクルスで使用
A33: きゅうり | B33: 本 | E33: =IFERROR(C33/D33,0) | F33: =IFERROR(E33/1.08,0) | G33: ピクルスで使用
A34: サラダ油 | B34: cc | E34: =IFERROR(C34/D34,0) | F34: =IFERROR(E34/1.08,0) | G34: ソース5で使用
A35: ケチャップ | B35: g | E35: =IFERROR(C35/D35,0) | F35: =IFERROR(E35/1.08,0) | G35: ソース5で使用
A36: りんご | B36: 個 | E36: =IFERROR(C36/D36,0) | F36: =IFERROR(E36/1.08,0) | G36: ソース5で使用
... A38: チリペッパーパウダー | B38: g | E38: =IFERROR(C38/D38,0) | F38: =IFERROR(E38/1.08,0) | G38: ソース5で使用（適量・初期0）
A39: エバラおろしのたれ | B39: cc | C39: 861.84 | D39: 1000 | E39: =IFERROR(C39/D39,0) | F39: =IFERROR(E39/1.08,0) | G39: ソース7（市販品） / トーホー / エバラ厨房応援団 おろしのたれレモン醤油味 1L 税抜798円
A40: 牛モモ(加熱用) | B40: g | C40: 2648.16 | D40: 1000 | E40: =IFERROR(C40/D40,0) | F40: =IFERROR(E40/1.08,0) | G40: ロービー用の原料肉（オーストラリア産）※歩留まり別途設定要 / レーベン / オーストラリア産 牛モモ(加熱用) 5.49kg 税抜2452円/kg
A41: ブロッコリー(冷凍) | B41: g | C41: 270 | D41: 500 | E41: =IFERROR(C41/D41,0) | F41: =IFERROR(E41/1.08,0) | G41: サイド「ブロッコリー」用（ユニフーズ500g） / トーホー / ユニフーズ ブロッコリー 500g 税抜250円
...

Sheet ソースレシピマスタ
A1: ソース名 | B1: 材料名 | C1: 分量 | D1: 単位 | E1: 税抜単位単価（円/単位） | F1: 材料費（円） | G1: 出来上がり寄与量（cc/g） | H1: 備考
A2: ハンバーグソース | B2: 味醂 | C2: 1080 | D2: cc | E2: =IFERROR(VLOOKUP(B2,レシピ材料マスタ!$A$2:$F$48,6,FALSE),0) | F2: =IFERROR(C2*E2,0) | G2: =IF(OR(D2="cc",D2="ml",D2="g"),IFERROR(C2,0),0) | H2: アルコールを飛ばす
A3: ハンバーグソース | B3: 醤油 | C3: 540 | D3: cc | E3: =IFERROR(VLOOKUP(B3,レシピ材料マスタ!$A$2:$F$48,6,FALSE),0) | F3: =IFERROR(C3*E3,0) | G3: =IF(OR(D3="cc",D3="ml",D3="g"),IFERROR(C3,0),0)
A4: ハンバーグソース | B4: マギーブイヨン | C4: 3 | D4: 個 | E4: =IFERROR(VLOOKUP(B4,レシピ材料マスタ!$A$2:$F$48,6,FALSE),0) | F4: =IFERROR(C4*E4,0) | G4: =IF(OR(D4="cc",D4="ml",D4="g"),IFERROR(C4,0),0)
A5: ハンバーグソース | B5: 顆粒だし | C5: 35 | D5: g | E5: =IFERROR(VLOOKUP(B5,レシピ材料マスタ!$A$2:$F$48,6,FALSE),0) | F5: =IFERROR(C5*E5,0) | G5: =IF(OR(D5="cc",D5="ml",D5="g"),IFERROR(C5,0),0)
A6: ハンバーグソース | B6: しめじ | C6: 4 | D6: pc | E6: =IFERROR(VLOOKUP(B6,レシピ材料マスタ!$A$2:$F$48,6,FALSE),0) | F6: =IFERROR(C6*E6,0) | G6: =IF(OR(D6="cc",D6="ml",D6="g"),IFERROR(C6,0),0) | H6: コンカッセ
A7: ハンバーグソース | B7: えのき | C7: 2 | D7: pc | E7: =IFERROR(VLOOKUP(B7,レシピ材料マスタ!$A$2:$F$48,6,FALSE),0) | F7: =IFERROR(C7*E7,0) | G7: =IF(OR(D7="cc",D7="ml",D7="g"),IFERROR(C7,0),0) | H7: コンカッセ
A8: ハンバーグソース | B8: エリンギ | C8: 2 | D8: pc | E8: =IFERROR(VLOOKUP(B8,レシピ材料マスタ!$A$2:$F$48,6,FALSE),0) | F8: =IFERROR(C8*E8,0) | G8: =IF(OR(D8="cc",D8="ml",D8="g"),IFERROR(C8,0),0) | H8: コンカッセ
A9: ハンバーグソース | B9: 水 | C9: 1500 | D9: cc | E9: =IFERROR(VLOOKUP(B9,レシピ材料マスタ!$A$2:$F$48,6,FALSE),0) | F9: =IFERROR(C9*E9,0) | G9: =IF(OR(D9="cc",D9="ml",D9="g"),IFERROR(C9,0),0)
A10: ハンバーグソース | B10: 粒マスタード | C10: =SUMIFS(G:G,A:A,"ハンバーグソース",B:B,"<>粒マスタード")*0.05 | D10: g | E10: =IFERROR(VLOOKUP(B10,レシピ材料マスタ!$A$2:$F$48,6,FALSE),0) | F10: =IFERROR(C10*E10,0) | G10: =IF(OR(D10="cc",D10="ml",D10="g"),IFERROR(C10,0),0) | H10: ソース全量×5%（自動計算）
A11: ブールブランソース | B11: 白ワイン | C11: 15 | D11: ml | E11: =IFERROR(VLOOKUP(B11,レシピ材料マスタ!$A$2:$F$48,6,FALSE),0) | F11: =IFERROR(C11*E11,0) | G11: =IF(OR(D11="cc",D11="ml",D11="g"),IFERROR(C11,0),0) | H11: 1食ぶん
A12: ブールブランソース | B12: クラム | C12: 2.5 | D12: g | E12: =IFERROR(VLOOKUP(B12,レシピ材料マスタ!$A$2:$F$48,6,FALSE),0) | F12: =IFERROR(C12*E12,0) | G12: =IF(OR(D12="cc",D12="ml",D12="g"),IFERROR(C12,0),0) | H12: 1食ぶん
A13: ブールブランソース | B13: 生クリーム | C13: 20 | D13: ml | E13: =IFERROR(VLOOKUP(B13,レシピ材料マスタ!$A$2:$F$48,6,FALSE),0) | F13: =IFERROR(C13*E13,0) | G13: =IF(OR(D13="cc",D13="ml",D13="g"),IFERROR(C13,0),0) | H13: 1食ぶん
A14: オニオンソース | B14: オニオンステーキソース | C14: 2000 | D14: cc | E14: =IFERROR(VLOOKUP(B14,レシピ材料マスタ!$A$2:$F$48,6,FALSE),0) | F14: =IFERROR(C14*E14,0) | G14: =IF(OR(D14="cc",D14="ml",D14="g"),IFERROR(C14,0),0) | H14: 2L=2000cc
A15: オニオンソース | B15: ニンニク醤油ソース | C15: 300 | D15: cc | E15: =IFERROR(VLOOKUP(B15,レシピ材料マスタ!$A$2:$F$48,6,FALSE),0) | F15: =IFERROR(C15*E15,0) | G15: =IF(OR(D15="cc",D15="ml",D15="g"),IFERROR(C15,0),0)
A16: ピクルス | B16: かんたん酢 | C16: 6000 | D16: ml | E16: =IFERROR(VLOOKUP(B16,レシピ材料マスタ!$A$2:$F$48,6,FALSE),0) | F16: =IFERROR(C16*E16,0) | G16: =IF(OR(D16="cc",D16="ml",D16="g"),IFERROR(C16,0),0) | H16: 6L=6000ml
A17: ピクルス | B17: 白ワインビネガー | C17: 1000 | D17: ml | E17: =IFERROR(VLOOKUP(B17,レシピ材料マスタ!$A$2:$F$48,6,FALSE),0) | F17: =IFERROR(C17*E17,0) | G17: =IF(OR(D17="cc",D17="ml",D17="g"),IFERROR(C17,0),0) | H17: 1L=1000ml
A18: ピクルス | B18: 塩 | C18: 175 | D18: g | E18: =IFERROR(VLOOKUP(B18,レシピ材料マスタ!$A$2:$F$48,6,FALSE),0) | F18: =IFERROR(C18*E18,0) | G18: =IF(OR(D18="cc",D18="ml",D18="g"),IFERROR(C18,0),0)
A19: ピクルス | B19: グラニュー糖 | C19: 150 | D19: g | E19: =IFERROR(VLOOKUP(B19,レシピ材料マスタ!$A$2:$F$48,6,FALSE),0) | F19: =IFERROR(C19*E19,0) | G19: =IF(OR(D19="cc",D19="ml",D19="g"),IFERROR(C19,0),0)
A20: ピクルス | B20: とうがらし | C20: 6 | D20: 本 | E20: =IFERROR(VLOOKUP(B20,レシピ材料マスタ!$A$2:$F$48,6,FALSE),0) | F20: =IFERROR(C20*E20,0) | G20: =IF(OR(D20="cc",D20="ml",D20="g"),IFERROR(C20,0),0)
A21: ピクルス | B21: 白粒こしょう | C21: 30 | D21: 粒 | E21: =IFERROR(VLOOKUP(B21,レシピ材料マスタ!$A$2:$F$48,6,FALSE),0) | F21: =IFERROR(C21*E21,0) | G21: =IF(OR(D21="cc",D21="ml",D21="g"),IFERROR(C21,0),0)
A22: ピクルス | B22: 玉ねぎ(個) | C22: 10 | D22: 個 | E22: =IFERROR(VLOOKUP(B22,レシピ材料マスタ!$A$2:$F$48,6,FALSE),0) | F22: =IFERROR(C22*E22,0) | G22: =IF(OR(D22="cc",D22="ml",D22="g"),IFERROR(C22,0),0) | H22: 追加材料
A23: ピクルス | B23: 大根 | C23: 3 | D23: 本 | E23: =IFERROR(VLOOKUP(B23,レシピ材料マスタ!$A$2:$F$48,6,FALSE),0) | F23: =IFERROR(C23*E23,0) | G23: =IF(OR(D23="cc",D23="ml",D23="g"),IFERROR(C23,0),0) | H23: 追加材料
A24: ピクルス | B24: 人参 | C24: 10 | D24: 本 | E24: =IFERROR(VLOOKUP(B24,レシピ材料マスタ!$A$2:$F$48,6,FALSE),0) | F24: =IFERROR(C24*E24,0) | G24: =IF(OR(D24="cc",D24="ml",D24="g"),IFERROR(C24,0),0) | H24: 追加材料
A25: ピクルス | B25: パプリカ | C25: 12 | D25: 個 | E25: =IFERROR(VLOOKUP(B25,レシピ材料マスタ!$A$2:$F$48,6,FALSE),0) | F25: =IFERROR(C25*E25,0) | G25: =IF(OR(D25="cc",D25="ml",D25="g"),IFERROR(C25,0),0) | H25: 追加材料
A26: ピクルス | B26: ヤングコーン(缶) | C26: 8 | D26: 缶 | E26: =IFERROR(VLOOKUP(B26,レシピ材料マスタ!$A$2:$F$48,6,FALSE),0) | F26: =IFERROR(C26*E26,0) | G26: =IF(OR(D26="cc",D26="ml",D26="g"),IFERROR(C26,0),0) | H26: 追加材料
A27: ピクルス | B27: きゅうり | C27: 12 | D27: 本 | E27: =IFERROR(VLOOKUP(B27,レシピ材料マスタ!$A$2:$F$48,6,FALSE),0) | F27: =IFERROR(C27*E27,0) | G27: =IF(OR(D27="cc",D27="ml",D27="g"),IFERROR(C27,0),0) | H27: 追加材料
A28: ポリネシアンソース | B28: サラダ油 | C28: 1080 | D28: cc | E28: =IFERROR(VLOOKUP(B28,レシピ材料マスタ!$A$2:$F$48,6,FALSE),0) | F28: =IFERROR(C28*E28,0) | G28: =IF(OR(D28="cc",D28="ml",D28="g"),IFERROR(C28,0),0)
A29: ポリネシアンソース | B29: ケチャップ | C29: 540 | D29: g | E29: =IFERROR(VLOOKUP(B29,レシピ材料マスタ!$A$2:$F$48,6,FALSE),0) | F29: =IFERROR(C29*E29,0) | G29: =IF(OR(D29="cc",D29="ml",D29="g"),IFERROR(C29,0),0)
A30: ポリネシアンソース | B30: 白ワイン | C30: 720 | D30: cc | E30: =IFERROR(VLOOKUP(B30,レシピ材料マスタ!$A$2:$F$48,6,FALSE),0) | F30: =IFERROR(C30*E30,0) | G30: =IF(OR(D30="cc",D30="ml",D30="g"),IFERROR(C30,0),0)
A31: ポリネシアンソース | B31: りんご | C31: 4 | D31: 個 | E31: =IFERROR(VLOOKUP(B31,レシピ材料マスタ!$A$2:$F$48,6,FALSE),0) | F31: =IFERROR(C31*E31,0) | G31: =IF(OR(D31="cc",D31="ml",D31="g"),IFERROR(C31,0),0)
A32: ポリネシアンソース | B32: 玉ねぎ(個) | C32: 4 | D32: 個 | E32: =IFERROR(VLOOKUP(B32,レシピ材料マスタ!$A$2:$F$48,6,FALSE),0) | F32: =IFERROR(C32*E32,0) | G32: =IF(OR(D32="cc",D32="ml",D32="g"),IFERROR(C32,0),0)
A33: ポリネシアンソース | B33: にんにく(個) | C33: 1 | D33: 個 | E33: =IFERROR(VLOOKUP(B33,レシピ材料マスタ!$A$2:$F$48,6,FALSE),0) | F33: =IFERROR(C33*E33,0) | G33: =IF(OR(D33="cc",D33="ml",D33="g"),IFERROR(C33,0),0)
A34: ポリネシアンソース | B34: 生姜 | C34: 0 | D34: g | E34: =IFERROR(VLOOKUP(B34,レシピ材料マスタ!$A$2:$F$48,6,FALSE),0) | F34: =IFERROR(C34*E34,0) | G34: =IF(OR(D34="cc",D34="ml",D34="g"),IFERROR(C34,0),0) | H34: 適量（未確定・要実測）
A35: ポリネシアンソース | B35: 醤油 | C35: 200 | D35: cc | E35: =IFERROR(VLOOKUP(B35,レシピ材料マスタ!$A$2:$F$48,6,FALSE),0) | F35: =IFERROR(C35*E35,0) | G35: =IF(OR(D35="cc",D35="ml",D35="g"),IFERROR(C35,0),0) | H35: ミキシング後に追加
A36: ポリネシアンソース | B36: チリペッパーパウダー | C36: 0 | D36: g | E36: =IFERROR(VLOOKUP(B36,レシピ材料マスタ!$A$2:$F$48,6,FALSE),0) | F36: =IFERROR(C36*E36,0) | G36: =IF(OR(D36="cc",D36="ml",D36="g"),IFERROR(C36,0),0) | H36: 適量・提供直前（未確定）
A37: ソースジャンジャンブル | B37: 玉ねぎ(g) | C37: 500 | D37: g | E37: =IFERROR(VLOOKUP(B37,レシピ材料マスタ!$A$2:$F$48,6,FALSE),0) | F37: =IFERROR(C37*E37,0) | G37: =IF(OR(D37="cc",D37="ml",D37="g"),IFERROR(C37,0),0) | H37: ざく切り
A38: ソースジャンジャンブル | B38: 生姜 | C38: 375 | D38: g | E38: =IFERROR(VLOOKUP(B38,レシピ材料マスタ!$A$2:$F$48,6,FALSE),0) | F38: =IFERROR(C38*E38,0) | G38: =IF(OR(D38="cc",D38="ml",D38="g"),IFERROR(C38,0),0)
A39: ソースジャンジャンブル | B39: にんにく(株) | C39: 1 | D39: 株 | E39: =IFERROR(VLOOKUP(B39,レシピ材料マスタ!$A$2:$F$48,6,FALSE),0) | F39: =IFERROR(C39*E39,0) | G39: =IF(OR(D39="cc",D39="ml",D39="g"),IFERROR(C39,0),0) | H39: 芽をとる
A40: ソースジャンジャンブル | B40: 味醂 | C40: 700 | D40: cc | E40: =IFERROR(VLOOKUP(B40,レシピ材料マスタ!$A$2:$F$48,6,FALSE),0) | F40: =IFERROR(C40*E40,0) | G40: =IF(OR(D40="cc",D40="ml",D40="g"),IFERROR(C40,0),0)
...

Sheet ソース定義マスタ
A1: ソース名 | B1: バッチ材料費（税抜・円） | C1: バッチ出来上がり量（cc/g 上書き可） | D1: 出来上がり量（最終） | E1: 単位原価（税抜・円/cc） | F1: 基準 | G1: 備考
A2: ハンバーグソース | B2: =SUMIFS(ソースレシピマスタ!$F$2:$F$56,ソースレシピマスタ!$A$2:$A$56,A2) | D2: =IF(ISNUMBER(C2),C2,SUMIFS(ソースレシピマスタ!$G$2:$G$56,ソースレシピマスタ!$A$2:$A$56,A2)) | E2: =IFERROR(B2/D2,0) | F2: batch | G2: バッチ合計（味醂+醤油+水+粒マスタード等）の合算をccベースで使用
A3: ブールブランソース | B3: =SUMIFS(ソースレシピマスタ!$F$2:$F$56,ソースレシピマスタ!$A$2:$A$56,A3) | C3: 30 | D3: =IF(ISNUMBER(C3),C3,SUMIFS(ソースレシピマスタ!$G$2:$G$56,ソースレシピマスタ!$A$2:$A$56,A3)) | E3: =IFERROR(B3/D3,0) | F3: per_serving | G3: 1食=30cc 完成。レシピは1食分で記載
A4: オニオンソース | B4: =SUMIFS(ソースレシピマスタ!$F$2:$F$56,ソースレシピマスタ!$A$2:$A$56,A4) | D4: =IF(ISNUMBER(C4),C4,SUMIFS(ソースレシピマスタ!$G$2:$G$56,ソースレシピマスタ!$A$2:$A$56,A4)) | E4: =IFERROR(B4/D4,0) | F4: batch | G4: オニオンステーキソース2L + ニンニク醤油ソース300cc
A5: ピクルス | B5: =SUMIFS(ソースレシピマスタ!$F$2:$F$56,ソースレシピマスタ!$A$2:$A$56,A5) | C5: 9200 | D5: =IF(ISNUMBER(C5),C5,SUMIFS(ソースレシピマスタ!$G$2:$G$56,ソースレシピマスタ!$A$2:$A$56,A5)) | E5: =IFERROR(B5/D5,0) | F5: batch | G5: 出来上がり9,200g＝生11,600g→可食部10,670g(廃棄率反映)→塩漬け×85%→水晒し×105%→水切り×97%。調味液は最終的に切るため重量加算なし
A6: ポリネシアンソース | B6: =SUMIFS(ソースレシピマスタ!$F$2:$F$56,ソースレシピマスタ!$A$2:$A$56,A6) | D6: =IF(ISNUMBER(C6),C6,SUMIFS(ソースレシピマスタ!$G$2:$G$56,ソースレシピマスタ!$A$2:$A$56,A6)) | E6: =IFERROR(B6/D6,0) | F6: batch | G6: サラダ油+ケチャップ+白ワイン+醤油の合算をccベースで使用
A7: ソースジャンジャンブル | B7: =SUMIFS(ソースレシピマスタ!$F$2:$F$56,ソースレシピマスタ!$A$2:$A$56,A7) | D7: =IF(ISNUMBER(C7),C7,SUMIFS(ソースレシピマスタ!$G$2:$G$56,ソースレシピマスタ!$A$2:$A$56,A7)) | E7: =IFERROR(B7/D7,0) | F7: batch | G7: 液体材料の合計をccベースで使用
A8: エバラおろしのたれ | B8: =SUMIFS(ソースレシピマスタ!$F$2:$F$56,ソースレシピマスタ!$A$2:$A$56,A8) | D8: =IF(ISNUMBER(C8),C8,SUMIFS(ソースレシピマスタ!$G$2:$G$56,ソースレシピマスタ!$A$2:$A$56,A8)) | E8: =IFERROR(B8/D8,0) | F8: market | G8: 市販品。1Lあたりの単位原価で計算（業者単価で自動更新）
A9: 粒マスタード単品 | B9: =SUMIFS(ソースレシピマスタ!$F$2:$F$56,ソースレシピマスタ!$A$2:$A$56,A9) | D9: =IF(ISNUMBER(C9),C9,SUMIFS(ソースレシピマスタ!$G$2:$G$56,ソースレシピマスタ!$A$2:$A$56,A9)) | E9: =IFERROR(B9/D9,0) | F9: condiment | G9: そのまま提供。g単位
A10: サラダベース | B10: =SUMIFS(ソースレシピマスタ!$F$2:$F$56,ソースレシピマスタ!$A$2:$A$56,A10) | D10: =IF(ISNUMBER(C10),C10,SUMIFS(ソースレシピマスタ!$G$2:$G$56,ソースレシピマスタ!$A$2:$A$56,A10)) | E10: =IFERROR(B10/D10,0) | F10: batch | G10: 出来上がり量は C列に実測値を入力（個・束だけのため自動合計不可）
A11: ポテトサラダ | B11: =SUMIFS(ソースレシピマスタ!$F$2:$F$56,ソースレシピマスタ!$A$2:$A$56,A11) | D11: =IF(ISNUMBER(C11),C11,SUMIFS(ソースレシピマスタ!$G$2:$G$56,ソースレシピマスタ!$A$2:$A$56,A11)) | E11: =IFERROR(B11/D11,0) | F11: batch | G11: レシピ未受領。出来上がり量と材料を後で入力
A12: 蒸し野菜 | B12: =SUMIFS(ソースレシピマスタ!$F$2:$F$56,ソースレシピマスタ!$A$2:$A$56,A12) | C12: 10280 | D12: =IF(ISNUMBER(C12),C12,SUMIFS(ソースレシピマスタ!$G$2:$G$56,ソースレシピマスタ!$A$2:$A$56,A12)) | E12: =IFERROR(B12/D12,0) | F12: batch | G12: 蒸し後重量(g)＝生重量12,850g×80%歩留まり仮算。キャベツ2×1200+白菜0.5×2500+にんじん3×180+玉ねぎ3×220+もやし8000

Sheet メニューマスタ
A1: ID | B1: メニュー名 | C1: 分類 | D1: 販売価格（税込） | E1: 食材1 | F1: 量1 | G1: 食材2 | H1: 量2 | I1: ピクルス | J1: ポテトサラダ | K1: 卵 | L1: ご飯 | M1: かぼちゃ | N1: 小エビ | O1: 有頭エビ | P1: 飲料ID | Q1: ソース1 | R1: ソース量1 | S1: ソース2 | T1: ソース量2 | U1: 主食材原価 | V1: サイド原価 | W1: 資材原価 | X1: ソース原価 | Y1: 飲料原価 | Z1: 合計原価（税抜） | AA1: 販売価格（税抜） | AB1: 原価率 | AC1: 利益率
A2: 1 | B2: 赤城牛のハンバーグ弁当 | C2: 黒弁当 | D2: 2000 | E2: 150gバーグ | F2: 1 | I2: 1 | J2: 1 | K2: 1 | L2: 1 | M2: 1 | N2: 1 | O2: 0 | P2: none | Q2: ハンバーグソース | R2: 40 | U2: =IFERROR(VLOOKUP(E2,食材マスタ!$A$2:$F$17,6,FALSE)*F2,0)+IFERROR(VLOOKUP(G2,食材マスタ!$A$2:$F$17,6,FALSE)*H2,0) | V2: =IFERROR(I2*IF($C2="黒弁当",IFERROR(VLOOKUP("ピクルス",サイドマスタ!$A:$F,3,FALSE),0),IFERROR(VLOOKUP("ピクルス",サイドマスタ!$A:$F,4,FALSE),0))*IFERROR(VLOOKUP("ピクルス",サイドマスタ!$A:$F,5,FALSE),0),0)+IFERROR(J2*IF($C2="黒弁当",IFERROR(VLOOKUP("ポテトサラダ",サイドマスタ!$A:$F,3,FALSE),0),IFERROR(VLOOKUP("ポテトサラダ",サイドマスタ!$A:$F,4,FALSE),0))*IFERROR(VLOOKUP("ポテトサラダ",サイドマスタ!$A:$F,5,FALSE),0),0)+IFERROR(K2*IF($C2="黒弁当",IFERROR(VLOOKUP("卵",サイドマスタ!$A:$F,3,FALSE),0),IFERROR(VLOOKUP("卵",サイドマスタ!$A:$F,4,FALSE),0))*IFERROR(VLOOKUP("卵",サイドマスタ!$A:$F,5,FALSE),0),0)+IFERROR(L2*IF($C2="黒弁当",IFERROR(VLOOKUP("ご飯",サイドマスタ!$A:$F,3,FALSE),0),IFERROR(VLOOKUP("ご飯",サイドマスタ!$A:$F,4,FALSE),0))*IFERROR(VLOOKUP("ご飯",サイドマスタ!$A:$F,5,FALSE),0),0)+IFERROR(M2*IF($C2="黒弁当",IFERROR(VLOOKUP("かぼちゃ",サイドマスタ!$A:$F,3,FALSE),0),IFERROR(VLOOKUP("かぼちゃ",サイドマスタ!$A:$F,4,FALSE),0))*IFERROR(VLOOKUP("かぼちゃ",サイドマスタ!$A:$F,5,FALSE),0),0)+IFERROR(N2*IF($C2="黒弁当",IFERROR(VLOOKUP("小エビ",サイドマスタ!$A:$F,3,FALSE),0),IFERROR(VLOOKUP("小エビ",サイドマスタ!$A:$F,4,FALSE),0))*IFERROR(VLOOKUP("小エビ",サイドマスタ!$A:$F,5,FALSE),0),0)+IFERROR(O2*IF($C2="黒弁当",IFERROR(VLOOKUP("有頭エビ",サイドマスタ!$A:$F,3,FALSE),0),IFERROR(VLOOKUP("有頭エビ",サイドマスタ!$A:$F,4,FALSE),0))*IFERROR(VLOOKUP("有頭エビ",サイドマスタ!$A:$F,5,FALSE),0),0)+IFERROR(IF($C2="黒弁当",IFERROR(VLOOKUP("サラダベース",サイドマスタ!$A:$F,3,FALSE),0),IFERROR(VLOOKUP("サラダベース",サイドマスタ!$A:$F,4,FALSE),0))*IFERROR(VLOOKUP("サラダベース",サイドマスタ!$A:$F,5,FALSE),0),0)+IFERROR(IF($C2="黒弁当",IFERROR(VLOOKUP("ミニトマト",サイドマスタ!$A:$F,3,FALSE),0),IFERROR(VLOOKUP("ミニトマト",サイドマスタ!$A:$F,4,FALSE),0))*IFERROR(VLOOKUP("ミニトマト",サイドマスタ!$A:$F,5,FALSE),0),0)+IFERROR(IF($C2="黒弁当",IFERROR(VLOOKUP("蒸し野菜",サイドマスタ!$A:$F,3,FALSE),0),IFERROR(VLOOKUP("蒸し野菜",サイドマスタ!$A:$F,4,FALSE),0))*IFERROR(VLOOKUP("蒸し野菜",サイドマスタ!$A:$F,5,FALSE),0),0)+IFERROR(IF($C2="黒弁当",IFERROR(VLOOKUP("ブロッコリー",サイドマスタ!$A:$F,3,FALSE),0),IFERROR(VLOOKUP("ブロッコリー",サイドマスタ!$A:$F,4,FALSE),0))*IFERROR(VLOOKUP("ブロッコリー",サイドマスタ!$A:$F,5,FALSE),0),0) | W2: =IF(C2="黒弁当",IFERROR(VLOOKUP("容器（黒）",資材マスタ!$A$2:$C$10,3,FALSE),0)+IFERROR(VLOOKUP("蓋（黒）",資材マスタ!$A$2:$C$10,3,FALSE),0),IFERROR(VLOOKUP("容器（新）",資材マスタ!$A$2:$C$10,3,FALSE),0)+IFERROR(VLOOKUP("蓋（新）",資材マスタ!$A$2:$C$10,3,FALSE),0))+IFERROR(VLOOKUP("箸",資材マスタ!$A$2:$C$10,3,FALSE),0)+IFERROR(VLOOKUP("ワサガード",資材マスタ!$A$2:$C$10,3,FALSE),0)+IFERROR(VLOOKUP("帯",資材マスタ!$A$2:$C$10,3,FALSE),0)+IFERROR(VLOOKUP("シーザードレッシング",資材マスタ!$A$2:$C$10,3,FALSE),0)+IFERROR(VLOOKUP("おしぼり",資材マスタ!$A$2:$C$10,3,FALSE),0) | X2: =IFERROR(VLOOKUP(Q2,ソース定義マスタ!$A$2:$E$12,5,FALSE)*R2,0)+IFERROR(VLOOKUP(S2,ソース定義マスタ!$A$2:$E$12,5,FALSE)*T2,0) | Y2: =IFERROR(VLOOKUP(P2,飲料マスタ!$A$2:$D$5,4,FALSE),0) | Z2: =U2+V2+W2+X2+Y2 | AA2: =D2/1.08 | AB2: =IFERROR(Z2/AA2,0) | AC2: =IFERROR(1-AB2,0)
A3: 2 | B3: 特選ハラミのステーキ弁当 | C3: 黒弁当 | D3: 2160 | E3: ハラミ | F3: 105 | I3: 1 | J3: 1 | K3: 1 | L3: 1 | M3: 1 | N3: 1 | O3: 0 | P3: none | Q3: オニオンソース | R3: 30 | U3: =IFERROR(VLOOKUP(E3,食材マスタ!$A$2:$F$17,6,FALSE)*F3,0)+IFERROR(VLOOKUP(G3,食材マスタ!$A$2:$F$17,6,FALSE)*H3,0) | V3: =IFERROR(I3*IF($C3="黒弁当",IFERROR(VLOOKUP("ピクルス",サイドマスタ!$A:$F,3,FALSE),0),IFERROR(VLOOKUP("ピクルス",サイドマスタ!$A:$F,4,FALSE),0))*IFERROR(VLOOKUP("ピクルス",サイドマスタ!$A:$F,5,FALSE),0),0)+IFERROR(J3*IF($C3="黒弁当",IFERROR(VLOOKUP("ポテトサラダ",サイドマスタ!$A:$F,3,FALSE),0),IFERROR(VLOOKUP("ポテトサラダ",サイドマスタ!$A:$F,4,FALSE),0))*IFERROR(VLOOKUP("ポテトサラダ",サイドマスタ!$A:$F,5,FALSE),0),0)+IFERROR(K3*IF($C3="黒弁当",IFERROR(VLOOKUP("卵",サイドマスタ!$A:$F,3,FALSE),0),IFERROR(VLOOKUP("卵",サイドマスタ!$A:$F,4,FALSE),0))*IFERROR(VLOOKUP("卵",サイドマスタ!$A:$F,5,FALSE),0),0)+IFERROR(L3*IF($C3="黒弁当",IFERROR(VLOOKUP("ご飯",サイドマスタ!$A:$F,3,FALSE),0),IFERROR(VLOOKUP("ご飯",サイドマスタ!$A:$F,4,FALSE),0))*IFERROR(VLOOKUP("ご飯",サイドマスタ!$A:$F,5,FALSE),0),0)+IFERROR(M3*IF($C3="黒弁当",IFERROR(VLOOKUP("かぼちゃ",サイドマスタ!$A:$F,3,FALSE),0),IFERROR(VLOOKUP("かぼちゃ",サイドマスタ!$A:$F,4,FALSE),0))*IFERROR(VLOOKUP("かぼちゃ",サイドマスタ!$A:$F,5,FALSE),0),0)+IFERROR(N3*IF($C3="黒弁当",IFERROR(VLOOKUP("小エビ",サイドマスタ!$A:$F,3,FALSE),0),IFERROR(VLOOKUP("小エビ",サイドマスタ!$A:$F,4,FALSE),0))*IFERROR(VLOOKUP("小エビ",サイドマスタ!$A:$F,5,FALSE),0),0)+IFERROR(O3*IF($C3="黒弁当",IFERROR(VLOOKUP("有頭エビ",サイドマスタ!$A:$F,3,FALSE),0),IFERROR(VLOOKUP("有頭エビ",サイドマスタ!$A:$F,4,FALSE),0))*IFERROR(VLOOKUP("有頭エビ",サイドマスタ!$A:$F,5,FALSE),0),0)+IFERROR(IF($C3="黒弁当",IFERROR(VLOOKUP("サラダベース",サイドマスタ!$A:$F,3,FALSE),0),IFERROR(VLOOKUP("サラダベース",サイドマスタ!$A:$F,4,FALSE),0))*IFERROR(VLOOKUP("サラダベース",サイドマスタ!$A:$F,5,FALSE),0),0)+IFERROR(IF($C3="黒弁当",IFERROR(VLOOKUP("ミニトマト",サイドマスタ!$A:$F,3,FALSE),0),IFERROR(VLOOKUP("ミニトマト",サイドマスタ!$A:$F,4,FALSE),0))*IFERROR(VLOOKUP("ミニトマト",サイドマスタ!$A:$F,5,FALSE),0),0)+IFERROR(IF($C3="黒弁当",IFERROR(VLOOKUP("蒸し野菜",サイドマスタ!$A:$F,3,FALSE),0),IFERROR(VLOOKUP("蒸し野菜",サイドマスタ!$A:$F,4,FALSE),0))*IFERROR(VLOOKUP("蒸し野菜",サイドマスタ!$A:$F,5,FALSE),0),0)+IFERROR(IF($C3="黒弁当",IFERROR(VLOOKUP("ブロッコリー",サイドマスタ!$A:$F,3,FALSE),0),IFERROR(VLOOKUP("ブロッコリー",サイドマスタ!$A:$F,4,FALSE),0))*IFERROR(VLOOKUP("ブロッコリー",サイドマスタ!$A:$F,5,FALSE),0),0) | W3: =IF(C3="黒弁当",IFERROR(VLOOKUP("容器（黒）",資材マスタ!$A$2:$C$10,3,FALSE),0)+IFERROR(VLOOKUP("蓋（黒）",資材マスタ!$A$2:$C$10,3,FALSE),0),IFERROR(VLOOKUP("容器（新）",資材マスタ!$A$2:$C$10,3,FALSE),0)+IFERROR(VLOOKUP("蓋（新）",資材マスタ!$A$2:$C$10,3,FALSE),0))+IFERROR(VLOOKUP("箸",資材マスタ!$A$2:$C$10,3,FALSE),0)+IFERROR(VLOOKUP("ワサガード",資材マスタ!$A$2:$C$10,3,FALSE),0)+IFERROR(VLOOKUP("帯",資材マスタ!$A$2:$C$10,3,FALSE),0)+IFERROR(VLOOKUP("シーザードレッシング",資材マスタ!$A$2:$C$10,3,FALSE),0)+IFERROR(VLOOKUP("おしぼり",資材マスタ!$A$2:$C$10,3,FALSE),0) | X3: =IFERROR(VLOOKUP(Q3,ソース定義マスタ!$A$2:$E$12,5,FALSE)*R3,0)+IFERROR(VLOOKUP(S3,ソース定義マスタ!$A$2:$E$12,5,FALSE)*T3,0) | Y3: =IFERROR(VLOOKUP(P3,飲料マスタ!$A$2:$D$5,4,FALSE),0) | Z3: =U3+V3+W3+X3+Y3 | AA3: =D3/1.08 | AB3: =IFERROR(Z3/AA3,0) | AC3: =IFERROR(1-AB3,0)
A4: 3 | B4: ローストビーフ弁当 | C4: 黒弁当 | D4: 2160 | E4: ロービー | F4: 85 | I4: 1 | J4: 1 | K4: 1 | L4: 1 | M4: 1 | N4: 1 | O4: 0 | P4: none | Q4: エバラおろしのたれ | R4: 30 | U4: =IFERROR(VLOOKUP(E4,食材マスタ!$A$2:$F$17,6,FALSE)*F4,0)+IFERROR(VLOOKUP(G4,食材マスタ!$A$2:$F$17,6,FALSE)*H4,0) | V4: =IFERROR(I4*IF($C4="黒弁当",IFERROR(VLOOKUP("ピクルス",サイドマスタ!$A:$F,3,FALSE),0),IFERROR(VLOOKUP("ピクルス",サイドマスタ!$A:$F,4,FALSE),0))*IFERROR(VLOOKUP("ピクルス",サイドマスタ!$A:$F,5,FALSE),0),0)+IFERROR(J4*IF($C4="黒弁当",IFERROR(VLOOKUP("ポテトサラダ",サイドマスタ!$A:$F,3,FALSE),0),IFERROR(VLOOKUP("ポテトサラダ",サイドマスタ!$A:$F,4,FALSE),0))*IFERROR(VLOOKUP("ポテトサラダ",サイドマスタ!$A:$F,5,FALSE),0),0)+IFERROR(K4*IF($C4="黒弁当",IFERROR(VLOOKUP("卵",サイドマスタ!$A:$F,3,FALSE),0),IFERROR(VLOOKUP("卵",サイドマスタ!$A:$F,4,FALSE),0))*IFERROR(VLOOKUP("卵",サイドマスタ!$A:$F,5,FALSE),0),0)+IFERROR(L4*IF($C4="黒弁当",IFERROR(VLOOKUP("ご飯",サイドマスタ!$A:$F,3,FALSE),0),IFERROR(VLOOKUP("ご飯",サイドマスタ!$A:$F,4,FALSE),0))*IFERROR(VLOOKUP("ご飯",サイドマスタ!$A:$F,5,FALSE),0),0)+IFERROR(M4*IF($C4="黒弁当",IFERROR(VLOOKUP("かぼちゃ",サイドマスタ!$A:$F,3,FALSE),0),IFERROR(VLOOKUP("かぼちゃ",サイドマスタ!$A:$F,4,FALSE),0))*IFERROR(VLOOKUP("かぼちゃ",サイドマスタ!$A:$F,5,FALSE),0),0)+IFERROR(N4*IF($C4="黒弁当",IFERROR(VLOOKUP("小エビ",サイドマスタ!$A:$F,3,FALSE),0),IFERROR(VLOOKUP("小エビ",サイドマスタ!$A:$F,4,FALSE),0))*IFERROR(VLOOKUP("小エビ",サイドマスタ!$A:$F,5,FALSE),0),0)+IFERROR(O4*IF($C4="黒弁当",IFERROR(VLOOKUP("有頭エビ",サイドマスタ!$A:$F,3,FALSE),0),IFERROR(VLOOKUP("有頭エビ",サイドマスタ!$A:$F,4,FALSE),0))*IFERROR(VLOOKUP("有頭エビ",サイドマスタ!$A:$F,5,FALSE),0),0)+IFERROR(IF($C4="黒弁当",IFERROR(VLOOKUP("サラダベース",サイドマスタ!$A:$F,3,FALSE),0),IFERROR(VLOOKUP("サラダベース",サイドマスタ!$A:$F,4,FALSE),0))*IFERROR(VLOOKUP("サラダベース",サイドマスタ!$A:$F,5,FALSE),0),0)+IFERROR(IF($C4="黒弁当",IFERROR(VLOOKUP("ミニトマト",サイドマスタ!$A:$F,3,FALSE),0),IFERROR(VLOOKUP("ミニトマト",サイドマスタ!$A:$F,4,FALSE),0))*IFERROR(VLOOKUP("ミニトマト",サイドマスタ!$A:$F,5,FALSE),0),0)+IFERROR(IF($C4="黒弁当",IFERROR(VLOOKUP("蒸し野菜",サイドマスタ!$A:$F,3,FALSE),0),IFERROR(VLOOKUP("蒸し野菜",サイドマスタ!$A:$F,4,FALSE),0))*IFERROR(VLOOKUP("蒸し野菜",サイドマスタ!$A:$F,5,FALSE),0),0)+IFERROR(IF($C4="黒弁当",IFERROR(VLOOKUP("ブロッコリー",サイドマスタ!$A:$F,3,FALSE),0),IFERROR(VLOOKUP("ブロッコリー",サイドマスタ!$A:$F,4,FALSE),0))*IFERROR(VLOOKUP("ブロッコリー",サイドマスタ!$A:$F,5,FALSE),0),0) | W4: =IF(C4="黒弁当",IFERROR(VLOOKUP("容器（黒）",資材マスタ!$A$2:$C$10,3,FALSE),0)+IFERROR(VLOOKUP("蓋（黒）",資材マスタ!$A$2:$C$10,3,FALSE),0),IFERROR(VLOOKUP("容器（新）",資材マスタ!$A$2:$C$10,3,FALSE),0)+IFERROR(VLOOKUP("蓋（新）",資材マスタ!$A$2:$C$10,3,FALSE),0))+IFERROR(VLOOKUP("箸",資材マスタ!$A$2:$C$10,3,FALSE),0)+IFERROR(VLOOKUP("ワサガード",資材マスタ!$A$2:$C$10,3,FALSE),0)+IFERROR(VLOOKUP("帯",資材マスタ!$A$2:$C$10,3,FALSE),0)+IFERROR(VLOOKUP("シーザードレッシング",資材マスタ!$A$2:$C$10,3,FALSE),0)+IFERROR(VLOOKUP("おしぼり",資材マスタ!$A$2:$C$10,3,FALSE),0) | X4: =IFERROR(VLOOKUP(Q4,ソース定義マスタ!$A$2:$E$12,5,FALSE)*R4,0)+IFERROR(VLOOKUP(S4,ソース定義マスタ!$A$2:$E$12,5,FALSE)*T4,0) | Y4: =IFERROR(VLOOKUP(P4,飲料マスタ!$A$2:$D$5,4,FALSE),0) | Z4: =U4+V4+W4+X4+Y4 | AA4: =D4/1.08 | AB4: =IFERROR(Z4/AA4,0) | AC4: =IFERROR(1-AB4,0)
A5: 4 | B5: 特選ハラミステーキとハンバーグの弁当 | C5: 黒弁当 | D5: 2200 | E5: ハラミ | F5: 52 | G5: 150gバーグ | H5: 0.5 | I5: 1 | J5: 1 | K5: 1 | L5: 1 | M5: 1 | N5: 1 | O5: 0 | P5: none | Q5: オニオンソース | R5: 20 | S5: ハンバーグソース | T5: 30 | U5: =IFERROR(VLOOKUP(E5,食材マスタ!$A$2:$F$17,6,FALSE)*F5,0)+IFERROR(VLOOKUP(G5,食材マスタ!$A$2:$F$17,6,FALSE)*H5,0) | V5: =IFERROR(I5*IF($C5="黒弁当",IFERROR(VLOOKUP("ピクルス",サイドマスタ!$A:$F,3,FALSE),0),IFERROR(VLOOKUP("ピクルス",サイドマスタ!$A:$F,4,FALSE),0))*IFERROR(VLOOKUP("ピクルス",サイドマスタ!$A:$F,5,FALSE),0),0)+IFERROR(J5*IF($C5="黒弁当",IFERROR(VLOOKUP("ポテトサラダ",サイドマスタ!$A:$F,3,FALSE),0),IFERROR(VLOOKUP("ポテトサラダ",サイドマスタ!$A:$F,4,FALSE),0))*IFERROR(VLOOKUP("ポテトサラダ",サイドマスタ!$A:$F,5,FALSE),0),0)+IFERROR(K5*IF($C5="黒弁当",IFERROR(VLOOKUP("卵",サイドマスタ!$A:$F,3,FALSE),0),IFERROR(VLOOKUP("卵",サイドマスタ!$A:$F,4,FALSE),0))*IFERROR(VLOOKUP("卵",サイドマスタ!$A:$F,5,FALSE),0),0)+IFERROR(L5*IF($C5="黒弁当",IFERROR(VLOOKUP("ご飯",サイドマスタ!$A:$F,3,FALSE),0),IFERROR(VLOOKUP("ご飯",サイドマスタ!$A:$F,4,FALSE),0))*IFERROR(VLOOKUP("ご飯",サイドマスタ!$A:$F,5,FALSE),0),0)+IFERROR(M5*IF($C5="黒弁当",IFERROR(VLOOKUP("かぼちゃ",サイドマスタ!$A:$F,3,FALSE),0),IFERROR(VLOOKUP("かぼちゃ",サイドマスタ!$A:$F,4,FALSE),0))*IFERROR(VLOOKUP("かぼちゃ",サイドマスタ!$A:$F,5,FALSE),0),0)+IFERROR(N5*IF($C5="黒弁当",IFERROR(VLOOKUP("小エビ",サイドマスタ!$A:$F,3,FALSE),0),IFERROR(VLOOKUP("小エビ",サイドマスタ!$A:$F,4,FALSE),0))*IFERROR(VLOOKUP("小エビ",サイドマスタ!$A:$F,5,FALSE),0),0)+IFERROR(O5*IF($C5="黒弁当",IFERROR(VLOOKUP("有頭エビ",サイドマスタ!$A:$F,3,FALSE),0),IFERROR(VLOOKUP("有頭エビ",サイドマスタ!$A:$F,4,FALSE),0))*IFERROR(VLOOKUP("有頭エビ",サイドマスタ!$A:$F,5,FALSE),0),0)+IFERROR(IF($C5="黒弁当",IFERROR(VLOOKUP("サラダベース",サイドマスタ!$A:$F,3,FALSE),0),IFERROR(VLOOKUP("サラダベース",サイドマスタ!$A:$F,4,FALSE),0))*IFERROR(VLOOKUP("サラダベース",サイドマスタ!$A:$F,5,FALSE),0),0)+IFERROR(IF($C5="黒弁当",IFERROR(VLOOKUP("ミニトマト",サイドマスタ!$A:$F,3,FALSE),0),IFERROR(VLOOKUP("ミニトマト",サイドマスタ!$A:$F,4,FALSE),0))*IFERROR(VLOOKUP("ミニトマト",サイドマスタ!$A:$F,5,FALSE),0),0)+IFERROR(IF($C5="黒弁当",IFERROR(VLOOKUP("蒸し野菜",サイドマスタ!$A:$F,3,FALSE),0),IFERROR(VLOOKUP("蒸し野菜",サイドマスタ!$A:$F,4,FALSE),0))*IFERROR(VLOOKUP("蒸し野菜",サイドマスタ!$A:$F,5,FALSE),0),0)+IFERROR(IF($C5="黒弁当",IFERROR(VLOOKUP("ブロッコリー",サイドマスタ!$A:$F,3,FALSE),0),IFERROR(VLOOKUP("ブロッコリー",サイドマスタ!$A:$F,4,FALSE),0))*IFERROR(VLOOKUP("ブロッコリー",サイドマスタ!$A:$F,5,FALSE),0),0) | W5: =IF(C5="黒弁当",IFERROR(VLOOKUP("容器（黒）",資材マスタ!$A$2:$C$10,3,FALSE),0)+IFERROR(VLOOKUP("蓋（黒）",資材マスタ!$A$2:$C$10,3,FALSE),0),IFERROR(VLOOKUP("容器（新）",資材マスタ!$A$2:$C$10,3,FALSE),0)+IFERROR(VLOOKUP("蓋（新）",資材マスタ!$A$2:$C$10,3,FALSE),0))+IFERROR(VLOOKUP("箸",資材マスタ!$A$2:$C$10,3,FALSE),0)+IFERROR(VLOOKUP("ワサガード",資材マスタ!$A$2:$C$10,3,FALSE),0)+IFERROR(VLOOKUP("帯",資材マスタ!$A$2:$C$10,3,FALSE),0)+IFERROR(VLOOKUP("シーザードレッシング",資材マスタ!$A$2:$C$10,3,FALSE),0)+IFERROR(VLOOKUP("おしぼり",資材マスタ!$A$2:$C$10,3,FALSE),0) | X5: =IFERROR(VLOOKUP(Q5,ソース定義マスタ!$A$2:$E$12,5,FALSE)*R5,0)+IFERROR(VLOOKUP(S5,ソース定義マスタ!$A$2:$E$12,5,FALSE)*T5,0) | Y5: =IFERROR(VLOOKUP(P5,飲料マスタ!$A$2:$D$5,4,FALSE),0) | Z5: =U5+V5+W5+X5+Y5 | AA5: =D5/1.08 | AB5: =IFERROR(Z5/AA5,0) | AC5: =IFERROR(1-AB5,0)
A6: 5 | B6: 特選ハラミステーキとローストビーフの弁当 | C6: 黒弁当 | D6: 2300 | E6: ハラミ | F6: 52 | G6: ロービー | H6: 42 | I6: 1 | J6: 1 | K6: 1 | L6: 1 | M6: 1 | N6: 1 | O6: 0 | P6: none | Q6: オニオンソース | R6: 20 | S6: エバラおろしのたれ | T6: 20 | U6: =IFERROR(VLOOKUP(E6,食材マスタ!$A$2:$F$17,6,FALSE)*F6,0)+IFERROR(VLOOKUP(G6,食材マスタ!$A$2:$F$17,6,FALSE)*H6,0) | V6: =IFERROR(I6*IF($C6="黒弁当",IFERROR(VLOOKUP("ピクルス",サイドマスタ!$A:$F,3,FALSE),0),IFERROR(VLOOKUP("ピクルス",サイドマスタ!$A:$F,4,FALSE),0))*IFERROR(VLOOKUP("ピクルス",サイドマスタ!$A:$F,5,FALSE),0),0)+IFERROR(J6*IF($C6="黒弁当",IFERROR(VLOOKUP("ポテトサラダ",サイドマスタ!$A:$F,3,FALSE),0),IFERROR(VLOOKUP("ポテトサラダ",サイドマスタ!$A:$F,4,FALSE),0))*IFERROR(VLOOKUP("ポテトサラダ",サイドマスタ!$A:$F,5,FALSE),0),0)+IFERROR(K6*IF($C6="黒弁当",IFERROR(VLOOKUP("卵",サイドマスタ!$A:$F,3,FALSE),0),IFERROR(VLOOKUP("卵",サイドマスタ!$A:$F,4,FALSE),0))*IFERROR(VLOOKUP("卵",サイドマスタ!$A:$F,5,FALSE),0),0)+IFERROR(L6*IF($C6="黒弁当",IFERROR(VLOOKUP("ご飯",サイドマスタ!$A:$F,3,FALSE),0),IFERROR(VLOOKUP("ご飯",サイドマスタ!$A:$F,4,FALSE),0))*IFERROR(VLOOKUP("ご飯",サイドマスタ!$A:$F,5,FALSE),0),0)+IFERROR(M6*IF($C6="黒弁当",IFERROR(VLOOKUP("かぼちゃ",サイドマスタ!$A:$F,3,FALSE),0),IFERROR(VLOOKUP("かぼちゃ",サイドマスタ!$A:$F,4,FALSE),0))*IFERROR(VLOOKUP("かぼちゃ",サイドマスタ!$A:$F,5,FALSE),0),0)+IFERROR(N6*IF($C6="黒弁当",IFERROR(VLOOKUP("小エビ",サイドマスタ!$A:$F,3,FALSE),0),IFERROR(VLOOKUP("小エビ",サイドマスタ!$A:$F,4,FALSE),0))*IFERROR(VLOOKUP("小エビ",サイドマスタ!$A:$F,5,FALSE),0),0)+IFERROR(O6*IF($C6="黒弁当",IFERROR(VLOOKUP("有頭エビ",サイドマスタ!$A:$F,3,FALSE),0),IFERROR(VLOOKUP("有頭エビ",サイドマスタ!$A:$F,4,FALSE),0))*IFERROR(VLOOKUP("有頭エビ",サイドマスタ!$A:$F,5,FALSE),0),0)+IFERROR(IF($C6="黒弁当",IFERROR(VLOOKUP("サラダベース",サイドマスタ!$A:$F,3,FALSE),0),IFERROR(VLOOKUP("サラダベース",サイドマスタ!$A:$F,4,FALSE),0))*IFERROR(VLOOKUP("サラダベース",サイドマスタ!$A:$F,5,FALSE),0),0)+IFERROR(IF($C6="黒弁当",IFERROR(VLOOKUP("ミニトマト",サイドマスタ!$A:$F,3,FALSE),0),IFERROR(VLOOKUP("ミニトマト",サイドマスタ!$A:$F,4,FALSE),0))*IFERROR(VLOOKUP("ミニトマト",サイドマスタ!$A:$F,5,FALSE),0),0)+IFERROR(IF($C6="黒弁当",IFERROR(VLOOKUP("蒸し野菜",サイドマスタ!$A:$F,3,FALSE),0),IFERROR(VLOOKUP("蒸し野菜",サイドマスタ!$A:$F,4,FALSE),0))*IFERROR(VLOOKUP("蒸し野菜",サイドマスタ!$A:$F,5,FALSE),0),0)+IFERROR(IF($C6="黒弁当",IFERROR(VLOOKUP("ブロッコリー",サイドマスタ!$A:$F,3,FALSE),0),IFERROR(VLOOKUP("ブロッコリー",サイドマスタ!$A:$F,4,FALSE),0))*IFERROR(VLOOKUP("ブロッコリー",サイドマスタ!$A:$F,5,FALSE),0),0) | W6: =IF(C6="黒弁当",IFERROR(VLOOKUP("容器（黒）",資材マスタ!$A$2:$C$10,3,FALSE),0)+IFERROR(VLOOKUP("蓋（黒）",資材マスタ!$A$2:$C$10,3,FALSE),0),IFERROR(VLOOKUP("容器（新）",資材マスタ!$A$2:$C$10,3,FALSE),0)+IFERROR(VLOOKUP("蓋（新）",資材マスタ!$A$2:$C$10,3,FALSE),0))+IFERROR(VLOOKUP("箸",資材マスタ!$A$2:$C$10,3,FALSE),0)+IFERROR(VLOOKUP("ワサガード",資材マスタ!$A$2:$C$10,3,FALSE),0)+IFERROR(VLOOKUP("帯",資材マスタ!$A$2:$C$10,3,FALSE),0)+IFERROR(VLOOKUP("シーザードレッシング",資材マスタ!$A$2:$C$10,3,FALSE),0)+IFERROR(VLOOKUP("おしぼり",資材マスタ!$A$2:$C$10,3,FALSE),0) | X6: =IFERROR(VLOOKUP(Q6,ソース定義マスタ!$A$2:$E$12,5,FALSE)*R6,0)+IFERROR(VLOOKUP(S6,ソース定義マスタ!$A$2:$E$12,5,FALSE)*T6,0) | Y6: =IFERROR(VLOOKUP(P6,飲料マスタ!$A$2:$D$5,4,FALSE),0) | Z6: =U6+V6+W6+X6+Y6 | AA6: =D6/1.08 | AB6: =IFERROR(Z6/AA6,0) | AC6: =IFERROR(1-AB6,0)
A7: 6 | B7: 特選ハラミのステーキとイベリコ豚の弁当 | C7: 黒弁当 | D7: 2500 | E7: ハラミ | F7: 52 | G7: イベリコ | H7: 50 | I7: 1 | J7: 1 | K7: 1 | L7: 1 | M7: 1 | N7: 1 | O7: 0 | P7: pet_free | Q7: オニオンソース | R7: 20 | S7: 粒マスタード単品 | T7: 15 | U7: =IFERROR(VLOOKUP(E7,食材マスタ!$A$2:$F$17,6,FALSE)*F7,0)+IFERROR(VLOOKUP(G7,食材マスタ!$A$2:$F$17,6,FALSE)*H7,0) | V7: =IFERROR(I7*IF($C7="黒弁当",IFERROR(VLOOKUP("ピクルス",サイドマスタ!$A:$F,3,FALSE),0),IFERROR(VLOOKUP("ピクルス",サイドマスタ!$A:$F,4,FALSE),0))*IFERROR(VLOOKUP("ピクルス",サイドマスタ!$A:$F,5,FALSE),0),0)+IFERROR(J7*IF($C7="黒弁当",IFERROR(VLOOKUP("ポテトサラダ",サイドマスタ!$A:$F,3,FALSE),0),IFERROR(VLOOKUP("ポテトサラダ",サイドマスタ!$A:$F,4,FALSE),0))*IFERROR(VLOOKUP("ポテトサラダ",サイドマスタ!$A:$F,5,FALSE),0),0)+IFERROR(K7*IF($C7="黒弁当",IFERROR(VLOOKUP("卵",サイドマスタ!$A:$F,3,FALSE),0),IFERROR(VLOOKUP("卵",サイドマスタ!$A:$F,4,FALSE),0))*IFERROR(VLOOKUP("卵",サイドマスタ!$A:$F,5,FALSE),0),0)+IFERROR(L7*IF($C7="黒弁当",IFERROR(VLOOKUP("ご飯",サイドマスタ!$A:$F,3,FALSE),0),IFERROR(VLOOKUP("ご飯",サイドマスタ!$A:$F,4,FALSE),0))*IFERROR(VLOOKUP("ご飯",サイドマスタ!$A:$F,5,FALSE),0),0)+IFERROR(M7*IF($C7="黒弁当",IFERROR(VLOOKUP("かぼちゃ",サイドマスタ!$A:$F,3,FALSE),0),IFERROR(VLOOKUP("かぼちゃ",サイドマスタ!$A:$F,4,FALSE),0))*IFERROR(VLOOKUP("かぼちゃ",サイドマスタ!$A:$F,5,FALSE),0),0)+IFERROR(N7*IF($C7="黒弁当",IFERROR(VLOOKUP("小エビ",サイドマスタ!$A:$F,3,FALSE),0),IFERROR(VLOOKUP("小エビ",サイドマスタ!$A:$F,4,FALSE),0))*IFERROR(VLOOKUP("小エビ",サイドマスタ!$A:$F,5,FALSE),0),0)+IFERROR(O7*IF($C7="黒弁当",IFERROR(VLOOKUP("有頭エビ",サイドマスタ!$A:$F,3,FALSE),0),IFERROR(VLOOKUP("有頭エビ",サイドマスタ!$A:$F,4,FALSE),0))*IFERROR(VLOOKUP("有頭エビ",サイドマスタ!$A:$F,5,FALSE),0),0)+IFERROR(IF($C7="黒弁当",IFERROR(VLOOKUP("サラダベース",サイドマスタ!$A:$F,3,FALSE),0),IFERROR(VLOOKUP("サラダベース",サイドマスタ!$A:$F,4,FALSE),0))*IFERROR(VLOOKUP("サラダベース",サイドマスタ!$A:$F,5,FALSE),0),0)+IFERROR(IF($C7="黒弁当",IFERROR(VLOOKUP("ミニトマト",サイドマスタ!$A:$F,3,FALSE),0),IFERROR(VLOOKUP("ミニトマト",サイドマスタ!$A:$F,4,FALSE),0))*IFERROR(VLOOKUP("ミニトマト",サイドマスタ!$A:$F,5,FALSE),0),0)+IFERROR(IF($C7="黒弁当",IFERROR(VLOOKUP("蒸し野菜",サイドマスタ!$A:$F,3,FALSE),0),IFERROR(VLOOKUP("蒸し野菜",サイドマスタ!$A:$F,4,FALSE),0))*IFERROR(VLOOKUP("蒸し野菜",サイドマスタ!$A:$F,5,FALSE),0),0)+IFERROR(IF($C7="黒弁当",IFERROR(VLOOKUP("ブロッコリー",サイドマスタ!$A:$F,3,FALSE),0),IFERROR(VLOOKUP("ブロッコリー",サイドマスタ!$A:$F,4,FALSE),0))*IFERROR(VLOOKUP("ブロッコリー",サイドマスタ!$A:$F,5,FALSE),0),0) | W7: =IF(C7="黒弁当",IFERROR(VLOOKUP("容器（黒）",資材マスタ!$A$2:$C$10,3,FALSE),0)+IFERROR(VLOOKUP("蓋（黒）",資材マスタ!$A$2:$C$10,3,FALSE),0),IFERROR(VLOOKUP("容器（新）",資材マスタ!$A$2:$C$10,3,FALSE),0)+IFERROR(VLOOKUP("蓋（新）",資材マスタ!$A$2:$C$10,3,FALSE),0))+IFERROR(VLOOKUP("箸",資材マスタ!$A$2:$C$10,3,FALSE),0)+IFERROR(VLOOKUP("ワサガード",資材マスタ!$A$2:$C$10,3,FALSE),0)+IFERROR(VLOOKUP("帯",資材マスタ!$A$2:$C$10,3,FALSE),0)+IFERROR(VLOOKUP("シーザードレッシング",資材マスタ!$A$2:$C$10,3,FALSE),0)+IFERROR(VLOOKUP("おしぼり",資材マスタ!$A$2:$C$10,3,FALSE),0) | X7: =IFERROR(VLOOKUP(Q7,ソース定義マスタ!$A$2:$E$12,5,FALSE)*R7,0)+IFERROR(VLOOKUP(S7,ソース定義マスタ!$A$2:$E$12,5,FALSE)*T7,0) | Y7: =IFERROR(VLOOKUP(P7,飲料マスタ!$A$2:$D$5,4,FALSE),0) | Z7: =U7+V7+W7+X7+Y7 | AA7: =D7/1.08 | AB7: =IFERROR(Z7/AA7,0) | AC7: =IFERROR(1-AB7,0)
A8: 7 | B8: 愛知県産真鯛の白ワイン蒸し弁当 | C8: 黒弁当 | D8: 2160 | E8: 鯛 | F8: 1 | I8: 1 | J8: 1 | K8: 1 | L8: 1 | M8: 1 | N8: 0 | O8: 1 | P8: none | Q8: ブールブランソース | R8: 30 | U8: =IFERROR(VLOOKUP(E8,食材マスタ!$A$2:$F$17,6,FALSE)*F8,0)+IFERROR(VLOOKUP(G8,食材マスタ!$A$2:$F$17,6,FALSE)*H8,0) | V8: =IFERROR(I8*IF($C8="黒弁当",IFERROR(VLOOKUP("ピクルス",サイドマスタ!$A:$F,3,FALSE),0),IFERROR(VLOOKUP("ピクルス",サイドマスタ!$A:$F,4,FALSE),0))*IFERROR(VLOOKUP("ピクルス",サイドマスタ!$A:$F,5,FALSE),0),0)+IFERROR(J8*IF($C8="黒弁当",IFERROR(VLOOKUP("ポテトサラダ",サイドマスタ!$A:$F,3,FALSE),0),IFERROR(VLOOKUP("ポテトサラダ",サイドマスタ!$A:$F,4,FALSE),0))*IFERROR(VLOOKUP("ポテトサラダ",サイドマスタ!$A:$F,5,FALSE),0),0)+IFERROR(K8*IF($C8="黒弁当",IFERROR(VLOOKUP("卵",サイドマスタ!$A:$F,3,FALSE),0),IFERROR(VLOOKUP("卵",サイドマスタ!$A:$F,4,FALSE),0))*IFERROR(VLOOKUP("卵",サイドマスタ!$A:$F,5,FALSE),0),0)+IFERROR(L8*IF($C8="黒弁当",IFERROR(VLOOKUP("ご飯",サイドマスタ!$A:$F,3,FALSE),0),IFERROR(VLOOKUP("ご飯",サイドマスタ!$A:$F,4,FALSE),0))*IFERROR(VLOOKUP("ご飯",サイドマスタ!$A:$F,5,FALSE),0),0)+IFERROR(M8*IF($C8="黒弁当",IFERROR(VLOOKUP("かぼちゃ",サイドマスタ!$A:$F,3,FALSE),0),IFERROR(VLOOKUP("かぼちゃ",サイドマスタ!$A:$F,4,FALSE),0))*IFERROR(VLOOKUP("かぼちゃ",サイドマスタ!$A:$F,5,FALSE),0),0)+IFERROR(N8*IF($C8="黒弁当",IFERROR(VLOOKUP("小エビ",サイドマスタ!$A:$F,3,FALSE),0),IFERROR(VLOOKUP("小エビ",サイドマスタ!$A:$F,4,FALSE),0))*IFERROR(VLOOKUP("小エビ",サイドマスタ!$A:$F,5,FALSE),0),0)+IFERROR(O8*IF($C8="黒弁当",IFERROR(VLOOKUP("有頭エビ",サイドマスタ!$A:$F,3,FALSE),0),IFERROR(VLOOKUP("有頭エビ",サイドマスタ!$A:$F,4,FALSE),0))*IFERROR(VLOOKUP("有頭エビ",サイドマスタ!$A:$F,5,FALSE),0),0)+IFERROR(IF($C8="黒弁当",IFERROR(VLOOKUP("サラダベース",サイドマスタ!$A:$F,3,FALSE),0),IFERROR(VLOOKUP("サラダベース",サイドマスタ!$A:$F,4,FALSE),0))*IFERROR(VLOOKUP("サラダベース",サイドマスタ!$A:$F,5,FALSE),0),0)+IFERROR(IF($C8="黒弁当",IFERROR(VLOOKUP("ミニトマト",サイドマスタ!$A:$F,3,FALSE),0),IFERROR(VLOOKUP("ミニトマト",サイドマスタ!$A:$F,4,FALSE),0))*IFERROR(VLOOKUP("ミニトマト",サイドマスタ!$A:$F,5,FALSE),0),0)+IFERROR(IF($C8="黒弁当",IFERROR(VLOOKUP("蒸し野菜",サイドマスタ!$A:$F,3,FALSE),0),IFERROR(VLOOKUP("蒸し野菜",サイドマスタ!$A:$F,4,FALSE),0))*IFERROR(VLOOKUP("蒸し野菜",サイドマスタ!$A:$F,5,FALSE),0),0)+IFERROR(IF($C8="黒弁当",IFERROR(VLOOKUP("ブロッコリー",サイドマスタ!$A:$F,3,FALSE),0),IFERROR(VLOOKUP("ブロッコリー",サイドマスタ!$A:$F,4,FALSE),0))*IFERROR(VLOOKUP("ブロッコリー",サイドマスタ!$A:$F,5,FALSE),0),0) | W8: =IF(C8="黒弁当",IFERROR(VLOOKUP("容器（黒）",資材マスタ!$A$2:$C$10,3,FALSE),0)+IFERROR(VLOOKUP("蓋（黒）",資材マスタ!$A$2:$C$10,3,FALSE),0),IFERROR(VLOOKUP("容器（新）",資材マスタ!$A$2:$C$10,3,FALSE),0)+IFERROR(VLOOKUP("蓋（新）",資材マスタ!$A$2:$C$10,3,FALSE),0))+IFERROR(VLOOKUP("箸",資材マスタ!$A$2:$C$10,3,FALSE),0)+IFERROR(VLOOKUP("ワサガード",資材マスタ!$A$2:$C$10,3,FALSE),0)+IFERROR(VLOOKUP("帯",資材マスタ!$A$2:$C$10,3,FALSE),0)+IFERROR(VLOOKUP("シーザードレッシング",資材マスタ!$A$2:$C$10,3,FALSE),0)+IFERROR(VLOOKUP("おしぼり",資材マスタ!$A$2:$C$10,3,FALSE),0) | X8: =IFERROR(VLOOKUP(Q8,ソース定義マスタ!$A$2:$E$12,5,FALSE)*R8,0)+IFERROR(VLOOKUP(S8,ソース定義マスタ!$A$2:$E$12,5,FALSE)*T8,0) | Y8: =IFERROR(VLOOKUP(P8,飲料マスタ!$A$2:$D$5,4,FALSE),0) | Z8: =U8+V8+W8+X8+Y8 | AA8: =D8/1.08 | AB8: =IFERROR(Z8/AA8,0) | AC8: =IFERROR(1-AB8,0)
A9: 8 | B9: アトランティックサーモンのロースト弁当 | C9: 黒弁当 | D9: 2000 | E9: サーモン | F9: 1 | I9: 1 | J9: 1 | K9: 1 | L9: 1 | M9: 1 | N9: 0 | O9: 1 | P9: none | Q9: ブールブランソース | R9: 30 | U9: =IFERROR(VLOOKUP(E9,食材マスタ!$A$2:$F$17,6,FALSE)*F9,0)+IFERROR(VLOOKUP(G9,食材マスタ!$A$2:$F$17,6,FALSE)*H9,0) | V9: =IFERROR(I9*IF($C9="黒弁当",IFERROR(VLOOKUP("ピクルス",サイドマスタ!$A:$F,3,FALSE),0),IFERROR(VLOOKUP("ピクルス",サイドマスタ!$A:$F,4,FALSE),0))*IFERROR(VLOOKUP("ピクルス",サイドマスタ!$A:$F,5,FALSE),0),0)+IFERROR(J9*IF($C9="黒弁当",IFERROR(VLOOKUP("ポテトサラダ",サイドマスタ!$A:$F,3,FALSE),0),IFERROR(VLOOKUP("ポテトサラダ",サイドマスタ!$A:$F,4,FALSE),0))*IFERROR(VLOOKUP("ポテトサラダ",サイドマスタ!$A:$F,5,FALSE),0),0)+IFERROR(K9*IF($C9="黒弁当",IFERROR(VLOOKUP("卵",サイドマスタ!$A:$F,3,FALSE),0),IFERROR(VLOOKUP("卵",サイドマスタ!$A:$F,4,FALSE),0))*IFERROR(VLOOKUP("卵",サイドマスタ!$A:$F,5,FALSE),0),0)+IFERROR(L9*IF($C9="黒弁当",IFERROR(VLOOKUP("ご飯",サイドマスタ!$A:$F,3,FALSE),0),IFERROR(VLOOKUP("ご飯",サイドマスタ!$A:$F,4,FALSE),0))*IFERROR(VLOOKUP("ご飯",サイドマスタ!$A:$F,5,FALSE),0),0)+IFERROR(M9*IF($C9="黒弁当",IFERROR(VLOOKUP("かぼちゃ",サイドマスタ!$A:$F,3,FALSE),0),IFERROR(VLOOKUP("かぼちゃ",サイドマスタ!$A:$F,4,FALSE),0))*IFERROR(VLOOKUP("かぼちゃ",サイドマスタ!$A:$F,5,FALSE),0),0)+IFERROR(N9*IF($C9="黒弁当",IFERROR(VLOOKUP("小エビ",サイドマスタ!$A:$F,3,FALSE),0),IFERROR(VLOOKUP("小エビ",サイドマスタ!$A:$F,4,FALSE),0))*IFERROR(VLOOKUP("小エビ",サイドマスタ!$A:$F,5,FALSE),0),0)+IFERROR(O9*IF($C9="黒弁当",IFERROR(VLOOKUP("有頭エビ",サイドマスタ!$A:$F,3,FALSE),0),IFERROR(VLOOKUP("有頭エビ",サイドマスタ!$A:$F,4,FALSE),0))*IFERROR(VLOOKUP("有頭エビ",サイドマスタ!$A:$F,5,FALSE),0),0)+IFERROR(IF($C9="黒弁当",IFERROR(VLOOKUP("サラダベース",サイドマスタ!$A:$F,3,FALSE),0),IFERROR(VLOOKUP("サラダベース",サイドマスタ!$A:$F,4,FALSE),0))*IFERROR(VLOOKUP("サラダベース",サイドマスタ!$A:$F,5,FALSE),0),0)+IFERROR(IF($C9="黒弁当",IFERROR(VLOOKUP("ミニトマト",サイドマスタ!$A:$F,3,FALSE),0),IFERROR(VLOOKUP("ミニトマト",サイドマスタ!$A:$F,4,FALSE),0))*IFERROR(VLOOKUP("ミニトマト",サイドマスタ!$A:$F,5,FALSE),0),0)+IFERROR(IF($C9="黒弁当",IFERROR(VLOOKUP("蒸し野菜",サイドマスタ!$A:$F,3,FALSE),0),IFERROR(VLOOKUP("蒸し野菜",サイドマスタ!$A:$F,4,FALSE),0))*IFERROR(VLOOKUP("蒸し野菜",サイドマスタ!$A:$F,5,FALSE),0),0)+IFERROR(IF($C9="黒弁当",IFERROR(VLOOKUP("ブロッコリー",サイドマスタ!$A:$F,3,FALSE),0),IFERROR(VLOOKUP("ブロッコリー",サイドマスタ!$A:$F,4,FALSE),0))*IFERROR(VLOOKUP("ブロッコリー",サイドマスタ!$A:$F,5,FALSE),0),0) | W9: =IF(C9="黒弁当",IFERROR(VLOOKUP("容器（黒）",資材マスタ!$A$2:$C$10,3,FALSE),0)+IFERROR(VLOOKUP("蓋（黒）",資材マスタ!$A$2:$C$10,3,FALSE),0),IFERROR(VLOOKUP("容器（新）",資材マスタ!$A$2:$C$10,3,FALSE),0)+IFERROR(VLOOKUP("蓋（新）",資材マスタ!$A$2:$C$10,3,FALSE),0))+IFERROR(VLOOKUP("箸",資材マスタ!$A$2:$C$10,3,FALSE),0)+IFERROR(VLOOKUP("ワサガード",資材マスタ!$A$2:$C$10,3,FALSE),0)+IFERROR(VLOOKUP("帯",資材マスタ!$A$2:$C$10,3,FALSE),0)+IFERROR(VLOOKUP("シーザードレッシング",資材マスタ!$A$2:$C$10,3,FALSE),0)+IFERROR(VLOOKUP("おしぼり",資材マスタ!$A$2:$C$10,3,FALSE),0) | X9: =IFERROR(VLOOKUP(Q9,ソース定義マスタ!$A$2:$E$12,5,FALSE)*R9,0)+IFERROR(VLOOKUP(S9,ソース定義マスタ!$A$2:$E$12,5,FALSE)*T9,0) | Y9: =IFERROR(VLOOKUP(P9,飲料マスタ!$A$2:$D$5,4,FALSE),0) | Z9: =U9+V9+W9+X9+Y9 | AA9: =D9/1.08 | AB9: =IFERROR(Z9/AA9,0) | AC9: =IFERROR(1-AB9,0)
A10: 9 | B10: 低糖質弁当 | C10: 黒弁当 | D10: 2300 | E10: 大豆バーグ | F10: 1 | G10: 豆腐 | H10: 0.33 | I10: 1 | J10: 1 | K10: 1 | L10: 0 | M10: 1 | N10: 1 | O10: 0 | P10: none | Q10: エバラおろしのたれ | R10: 30 | U10: =IFERROR(VLOOKUP(E10,食材マスタ!$A$2:$F$17,6,FALSE)*F10,0)+IFERROR(VLOOKUP(G10,食材マスタ!$A$2:$F$17,6,FALSE)*H10,0) | V10: =IFERROR(I10*IF($C10="黒弁当",IFERROR(VLOOKUP("ピクルス",サイドマスタ!$A:$F,3,FALSE),0),IFERROR(VLOOKUP("ピクルス",サイドマスタ!$A:$F,4,FALSE),0))*IFERROR(VLOOKUP("ピクルス",サイドマスタ!$A:$F,5,FALSE),0),0)+IFERROR(J10*IF($C10="黒弁当",IFERROR(VLOOKUP("ポテトサラダ",サイドマスタ!$A:$F,3,FALSE),0),IFERROR(VLOOKUP("ポテトサラダ",サイドマスタ!$A:$F,4,FALSE),0))*IFERROR(VLOOKUP("ポテトサラダ",サイドマスタ!$A:$F,5,FALSE),0),0)+IFERROR(K10*IF($C10="黒弁当",IFERROR(VLOOKUP("卵",サイドマスタ!$A:$F,3,FALSE),0),IFERROR(VLOOKUP("卵",サイドマスタ!$A:$F,4,FALSE),0))*IFERROR(VLOOKUP("卵",サイドマスタ!$A:$F,5,FALSE),0),0)+IFERROR(L10*IF($C10="黒弁当",IFERROR(VLOOKUP("ご飯",サイドマスタ!$A:$F,3,FALSE),0),IFERROR(VLOOKUP("ご飯",サイドマスタ!$A:$F,4,FALSE),0))*IFERROR(VLOOKUP("ご飯",サイドマスタ!$A:$F,5,FALSE),0),0)+IFERROR(M10*IF($C10="黒弁当",IFERROR(VLOOKUP("かぼちゃ",サイドマスタ!$A:$F,3,FALSE),0),IFERROR(VLOOKUP("かぼちゃ",サイドマスタ!$A:$F,4,FALSE),0))*IFERROR(VLOOKUP("かぼちゃ",サイドマスタ!$A:$F,5,FALSE),0),0)+IFERROR(N10*IF($C10="黒弁当",IFERROR(VLOOKUP("小エビ",サイドマスタ!$A:$F,3,FALSE),0),IFERROR(VLOOKUP("小エビ",サイドマスタ!$A:$F,4,FALSE),0))*IFERROR(VLOOKUP("小エビ",サイドマスタ!$A:$F,5,FALSE),0),0)+IFERROR(O10*IF($C10="黒弁当",IFERROR(VLOOKUP("有頭エビ",サイドマスタ!$A:$F,3,FALSE),0),IFERROR(VLOOKUP("有頭エビ",サイドマスタ!$A:$F,4,FALSE),0))*IFERROR(VLOOKUP("有頭エビ",サイドマスタ!$A:$F,5,FALSE),0),0)+IFERROR(IF($C10="黒弁当",IFERROR(VLOOKUP("サラダベース",サイドマスタ!$A:$F,3,FALSE),0),IFERROR(VLOOKUP("サラダベース",サイドマスタ!$A:$F,4,FALSE),0))*IFERROR(VLOOKUP("サラダベース",サイドマスタ!$A:$F,5,FALSE),0),0)+IFERROR(IF($C10="黒弁当",IFERROR(VLOOKUP("ミニトマト",サイドマスタ!$A:$F,3,FALSE),0),IFERROR(VLOOKUP("ミニトマト",サイドマスタ!$A:$F,4,FALSE),0))*IFERROR(VLOOKUP("ミニトマト",サイドマスタ!$A:$F,5,FALSE),0),0)+IFERROR(IF($C10="黒弁当",IFERROR(VLOOKUP("蒸し野菜",サイドマスタ!$A:$F,3,FALSE),0),IFERROR(VLOOKUP("蒸し野菜",サイドマスタ!$A:$F,4,FALSE),0))*IFERROR(VLOOKUP("蒸し野菜",サイドマスタ!$A:$F,5,FALSE),0),0)+IFERROR(IF($C10="黒弁当",IFERROR(VLOOKUP("ブロッコリー",サイドマスタ!$A:$F,3,FALSE),0),IFERROR(VLOOKUP("ブロッコリー",サイドマスタ!$A:$F,4,FALSE),0))*IFERROR(VLOOKUP("ブロッコリー",サイドマスタ!$A:$F,5,FALSE),0),0) | W10: =IF(C10="黒弁当",IFERROR(VLOOKUP("容器（黒）",資材マスタ!$A$2:$C$10,3,FALSE),0)+IFERROR(VLOOKUP("蓋（黒）",資材マスタ!$A$2:$C$10,3,FALSE),0),IFERROR(VLOOKUP("容器（新）",資材マスタ!$A$2:$C$10,3,FALSE),0)+IFERROR(VLOOKUP("蓋（新）",資材マスタ!$A$2:$C$10,3,FALSE),0))+IFERROR(VLOOKUP("箸",資材マスタ!$A$2:$C$10,3,FALSE),0)+IFERROR(VLOOKUP("ワサガード",資材マスタ!$A$2:$C$10,3,FALSE),0)+IFERROR(VLOOKUP("帯",資材マスタ!$A$2:$C$10,3,FALSE),0)+IFERROR(VLOOKUP("シーザードレッシング",資材マスタ!$A$2:$C$10,3,FALSE),0)+IFERROR(VLOOKUP("おしぼり",資材マスタ!$A$2:$C$10,3,FALSE),0) | X10: =IFERROR(VLOOKUP(Q10,ソース定義マスタ!$A$2:$E$12,5,FALSE)*R10,0)+IFERROR(VLOOKUP(S10,ソース定義マスタ!$A$2:$E$12,5,FALSE)*T10,0) | Y10: =IFERROR(VLOOKUP(P10,飲料マスタ!$A$2:$D$5,4,FALSE),0) | Z10: =U10+V10+W10+X10+Y10 | AA10: =D10/1.08 | AB10: =IFERROR(Z10/AA10,0) | AC10: =IFERROR(1-AB10,0)
A11: 10 | B11: 赤城牛ミスジとハラミのステーキ弁当 | C11: 黒弁当 | D11: 2800 | E11: ミスジ | F11: 50 | G11: ハラミ | H11: 52 | I11: 1 | J11: 1 | K11: 1 | L11: 1 | M11: 1 | N11: 1 | O11: 0 | P11: none | Q11: エバラおろしのたれ | R11: 20 | S11: オニオンソース | T11: 20 | U11: =IFERROR(VLOOKUP(E11,食材マスタ!$A$2:$F$17,6,FALSE)*F11,0)+IFERROR(VLOOKUP(G11,食材マスタ!$A$2:$F$17,6,FALSE)*H11,0) | V11: =IFERROR(I11*IF($C11="黒弁当",IFERROR(VLOOKUP("ピクルス",サイドマスタ!$A:$F,3,FALSE),0),IFERROR(VLOOKUP("ピクルス",サイドマスタ!$A:$F,4,FALSE),0))*IFERROR(VLOOKUP("ピクルス",サイドマスタ!$A:$F,5,FALSE),0),0)+IFERROR(J11*IF($C11="黒弁当",IFERROR(VLOOKUP("ポテトサラダ",サイドマスタ!$A:$F,3,FALSE),0),IFERROR(VLOOKUP("ポテトサラダ",サイドマスタ!$A:$F,4,FALSE),0))*IFERROR(VLOOKUP("ポテトサラダ",サイドマスタ!$A:$F,5,FALSE),0),0)+IFERROR(K11*IF($C11="黒弁当",IFERROR(VLOOKUP("卵",サイドマスタ!$A:$F,3,FALSE),0),IFERROR(VLOOKUP("卵",サイドマスタ!$A:$F,4,FALSE),0))*IFERROR(VLOOKUP("卵",サイドマスタ!$A:$F,5,FALSE),0),0)+IFERROR(L11*IF($C11="黒弁当",IFERROR(VLOOKUP("ご飯",サイドマスタ!$A:$F,3,FALSE),0),IFERROR(VLOOKUP("ご飯",サイドマスタ!$A:$F,4,FALSE),0))*IFERROR(VLOOKUP("ご飯",サイドマスタ!$A:$F,5,FALSE),0),0)+IFERROR(M11*IF($C11="黒弁当",IFERROR(VLOOKUP("かぼちゃ",サイドマスタ!$A:$F,3,FALSE),0),IFERROR(VLOOKUP("かぼちゃ",サイドマスタ!$A:$F,4,FALSE),0))*IFERROR(VLOOKUP("かぼちゃ",サイドマスタ!$A:$F,5,FALSE),0),0)+IFERROR(N11*IF($C11="黒弁当",IFERROR(VLOOKUP("小エビ",サイドマスタ!$A:$F,3,FALSE),0),IFERROR(VLOOKUP("小エビ",サイドマスタ!$A:$F,4,FALSE),0))*IFERROR(VLOOKUP("小エビ",サイドマスタ!$A:$F,5,FALSE),0),0)+IFERROR(O11*IF($C11="黒弁当",IFERROR(VLOOKUP("有頭エビ",サイドマスタ!$A:$F,3,FALSE),0),IFERROR(VLOOKUP("有頭エビ",サイドマスタ!$A:$F,4,FALSE),0))*IFERROR(VLOOKUP("有頭エビ",サイドマスタ!$A:$F,5,FALSE),0),0)+IFERROR(IF($C11="黒弁当",IFERROR(VLOOKUP("サラダベース",サイドマスタ!$A:$F,3,FALSE),0),IFERROR(VLOOKUP("サラダベース",サイドマスタ!$A:$F,4,FALSE),0))*IFERROR(VLOOKUP("サラダベース",サイドマスタ!$A:$F,5,FALSE),0),0)+IFERROR(IF($C11="黒弁当",IFERROR(VLOOKUP("ミニトマト",サイドマスタ!$A:$F,3,FALSE),0),IFERROR(VLOOKUP("ミニトマト",サイドマスタ!$A:$F,4,FALSE),0))*IFERROR(VLOOKUP("ミニトマト",サイドマスタ!$A:$F,5,FALSE),0),0)+IFERROR(IF($C11="黒弁当",IFERROR(VLOOKUP("蒸し野菜",サイドマスタ!$A:$F,3,FALSE),0),IFERROR(VLOOKUP("蒸し野菜",サイドマスタ!$A:$F,4,FALSE),0))*IFERROR(VLOOKUP("蒸し野菜",サイドマスタ!$A:$F,5,FALSE),0),0)+IFERROR(IF($C11="黒弁当",IFERROR(VLOOKUP("ブロッコリー",サイドマスタ!$A:$F,3,FALSE),0),IFERROR(VLOOKUP("ブロッコリー",サイドマスタ!$A:$F,4,FALSE),0))*IFERROR(VLOOKUP("ブロッコリー",サイドマスタ!$A:$F,5,FALSE),0),0) | W11: =IF(C11="黒弁当",IFERROR(VLOOKUP("容器（黒）",資材マスタ!$A$2:$C$10,3,FALSE),0)+IFERROR(VLOOKUP("蓋（黒）",資材マスタ!$A$2:$C$10,3,FALSE),0),IFERROR(VLOOKUP("容器（新）",資材マスタ!$A$2:$C$10,3,FALSE),0)+IFERROR(VLOOKUP("蓋（新）",資材マスタ!$A$2:$C$10,3,FALSE),0))+IFERROR(VLOOKUP("箸",資材マスタ!$A$2:$C$10,3,FALSE),0)+IFERROR(VLOOKUP("ワサガード",資材マスタ!$A$2:$C$10,3,FALSE),0)+IFERROR(VLOOKUP("帯",資材マスタ!$A$2:$C$10,3,FALSE),0)+IFERROR(VLOOKUP("シーザードレッシング",資材マスタ!$A$2:$C$10,3,FALSE),0)+IFERROR(VLOOKUP("おしぼり",資材マスタ!$A$2:$C$10,3,FALSE),0) | X11: =IFERROR(VLOOKUP(Q11,ソース定義マスタ!$A$2:$E$12,5,FALSE)*R11,0)+IFERROR(VLOOKUP(S11,ソース定義マスタ!$A$2:$E$12,5,FALSE)*T11,0) | Y11: =IFERROR(VLOOKUP(P11,飲料マスタ!$A$2:$D$5,4,FALSE),0) | Z11: =U11+V11+W11+X11+Y11 | AA11: =D11/1.08 | AB11: =IFERROR(Z11/AA11,0) | AC11: =IFERROR(1-AB11,0)
A12: 11 | B12: 赤城牛ミスジのステーキ弁当 | C12: 黒弁当 | D12: 3000 | E12: ミスジ | F12: 100 | I12: 1 | J12: 1 | K12: 1 | L12: 1 | M12: 1 | N12: 1 | O12: 0 | P12: pet_free | Q12: エバラおろしのたれ | R12: 30 | U12: =IFERROR(VLOOKUP(E12,食材マスタ!$A$2:$F$17,6,FALSE)*F12,0)+IFERROR(VLOOKUP(G12,食材マスタ!$A$2:$F$17,6,FALSE)*H12,0) | V12: =IFERROR(I12*IF($C12="黒弁当",IFERROR(VLOOKUP("ピクルス",サイドマスタ!$A:$F,3,FALSE),0),IFERROR(VLOOKUP("ピクルス",サイドマスタ!$A:$F,4,FALSE),0))*IFERROR(VLOOKUP("ピクルス",サイドマスタ!$A:$F,5,FALSE),0),0)+IFERROR(J12*IF($C12="黒弁当",IFERROR(VLOOKUP("ポテトサラダ",サイドマスタ!$A:$F,3,FALSE),0),IFERROR(VLOOKUP("ポテトサラダ",サイドマスタ!$A:$F,4,FALSE),0))*IFERROR(VLOOKUP("ポテトサラダ",サイドマスタ!$A:$F,5,FALSE),0),0)+IFERROR(K12*IF($C12="黒弁当",IFERROR(VLOOKUP("卵",サイドマスタ!$A:$F,3,FALSE),0),IFERROR(VLOOKUP("卵",サイドマスタ!$A:$F,4,FALSE),0))*IFERROR(VLOOKUP("卵",サイドマスタ!$A:$F,5,FALSE),0),0)+IFERROR(L12*IF($C12="黒弁当",IFERROR(VLOOKUP("ご飯",サイドマスタ!$A:$F,3,FALSE),0),IFERROR(VLOOKUP("ご飯",サイドマスタ!$A:$F,4,FALSE),0))*IFERROR(VLOOKUP("ご飯",サイドマスタ!$A:$F,5,FALSE),0),0)+IFERROR(M12*IF($C12="黒弁当",IFERROR(VLOOKUP("かぼちゃ",サイドマスタ!$A:$F,3,FALSE),0),IFERROR(VLOOKUP("かぼちゃ",サイドマスタ!$A:$F,4,FALSE),0))*IFERROR(VLOOKUP("かぼちゃ",サイドマスタ!$A:$F,5,FALSE),0),0)+IFERROR(N12*IF($C12="黒弁当",IFERROR(VLOOKUP("小エビ",サイドマスタ!$A:$F,3,FALSE),0),IFERROR(VLOOKUP("小エビ",サイドマスタ!$A:$F,4,FALSE),0))*IFERROR(VLOOKUP("小エビ",サイドマスタ!$A:$F,5,FALSE),0),0)+IFERROR(O12*IF($C12="黒弁当",IFERROR(VLOOKUP("有頭エビ",サイドマスタ!$A:$F,3,FALSE),0),IFERROR(VLOOKUP("有頭エビ",サイドマスタ!$A:$F,4,FALSE),0))*IFERROR(VLOOKUP("有頭エビ",サイドマスタ!$A:$F,5,FALSE),0),0)+IFERROR(IF($C12="黒弁当",IFERROR(VLOOKUP("サラダベース",サイドマスタ!$A:$F,3,FALSE),0),IFERROR(VLOOKUP("サラダベース",サイドマスタ!$A:$F,4,FALSE),0))*IFERROR(VLOOKUP("サラダベース",サイドマスタ!$A:$F,5,FALSE),0),0)+IFERROR(IF($C12="黒弁当",IFERROR(VLOOKUP("ミニトマト",サイドマスタ!$A:$F,3,FALSE),0),IFERROR(VLOOKUP("ミニトマト",サイドマスタ!$A:$F,4,FALSE),0))*IFERROR(VLOOKUP("ミニトマト",サイドマスタ!$A:$F,5,FALSE),0),0)+IFERROR(IF($C12="黒弁当",IFERROR(VLOOKUP("蒸し野菜",サイドマスタ!$A:$F,3,FALSE),0),IFERROR(VLOOKUP("蒸し野菜",サイドマスタ!$A:$F,4,FALSE),0))*IFERROR(VLOOKUP("蒸し野菜",サイドマスタ!$A:$F,5,FALSE),0),0)+IFERROR(IF($C12="黒弁当",IFERROR(VLOOKUP("ブロッコリー",サイドマスタ!$A:$F,3,FALSE),0),IFERROR(VLOOKUP("ブロッコリー",サイドマスタ!$A:$F,4,FALSE),0))*IFERROR(VLOOKUP("ブロッコリー",サイドマスタ!$A:$F,5,FALSE),0),0) | W12: =IF(C12="黒弁当",IFERROR(VLOOKUP("容器（黒）",資材マスタ!$A$2:$C$10,3,FALSE),0)+IFERROR(VLOOKUP("蓋（黒）",資材マスタ!$A$2:$C$10,3,FALSE),0),IFERROR(VLOOKUP("容器（新）",資材マスタ!$A$2:$C$10,3,FALSE),0)+IFERROR(VLOOKUP("蓋（新）",資材マスタ!$A$2:$C$10,3,FALSE),0))+IFERROR(VLOOKUP("箸",資材マスタ!$A$2:$C$10,3,FALSE),0)+IFERROR(VLOOKUP("ワサガード",資材マスタ!$A$2:$C$10,3,FALSE),0)+IFERROR(VLOOKUP("帯",資材マスタ!$A$2:$C$10,3,FALSE),0)+IFERROR(VLOOKUP("シーザードレッシング",資材マスタ!$A$2:$C$10,3,FALSE),0)+IFERROR(VLOOKUP("おしぼり",資材マスタ!$A$2:$C$10,3,FALSE),0) | X12: =IFERROR(VLOOKUP(Q12,ソース定義マスタ!$A$2:$E$12,5,FALSE)*R12,0)+IFERROR(VLOOKUP(S12,ソース定義マスタ!$A$2:$E$12,5,FALSE)*T12,0) | Y12: =IFERROR(VLOOKUP(P12,飲料マスタ!$A$2:$D$5,4,FALSE),0) | Z12: =U12+V12+W12+X12+Y12 | AA12: =D12/1.08 | AB12: =IFERROR(Z12/AA12,0) | AC12: =IFERROR(1-AB12,0)
A13: 12 | B13: 厳選和牛のステーキ弁当 | C13: 黒弁当 | D13: 3240 | E13: 厳選和牛 | F13: 110 | I13: 1 | J13: 1 | K13: 1 | L13: 1 | M13: 1 | N13: 1 | O13: 0 | P13: pet_free | Q13: エバラおろしのたれ | R13: 30 | U13: =IFERROR(VLOOKUP(E13,食材マスタ!$A$2:$F$17,6,FALSE)*F13,0)+IFERROR(VLOOKUP(G13,食材マスタ!$A$2:$F$17,6,FALSE)*H13,0) | V13: =IFERROR(I13*IF($C13="黒弁当",IFERROR(VLOOKUP("ピクルス",サイドマスタ!$A:$F,3,FALSE),0),IFERROR(VLOOKUP("ピクルス",サイドマスタ!$A:$F,4,FALSE),0))*IFERROR(VLOOKUP("ピクルス",サイドマスタ!$A:$F,5,FALSE),0),0)+IFERROR(J13*IF($C13="黒弁当",IFERROR(VLOOKUP("ポテトサラダ",サイドマスタ!$A:$F,3,FALSE),0),IFERROR(VLOOKUP("ポテトサラダ",サイドマスタ!$A:$F,4,FALSE),0))*IFERROR(VLOOKUP("ポテトサラダ",サイドマスタ!$A:$F,5,FALSE),0),0)+IFERROR(K13*IF($C13="黒弁当",IFERROR(VLOOKUP("卵",サイドマスタ!$A:$F,3,FALSE),0),IFERROR(VLOOKUP("卵",サイドマスタ!$A:$F,4,FALSE),0))*IFERROR(VLOOKUP("卵",サイドマスタ!$A:$F,5,FALSE),0),0)+IFERROR(L13*IF($C13="黒弁当",IFERROR(VLOOKUP("ご飯",サイドマスタ!$A:$F,3,FALSE),0),IFERROR(VLOOKUP("ご飯",サイドマスタ!$A:$F,4,FALSE),0))*IFERROR(VLOOKUP("ご飯",サイドマスタ!$A:$F,5,FALSE),0),0)+IFERROR(M13*IF($C13="黒弁当",IFERROR(VLOOKUP("かぼちゃ",サイドマスタ!$A:$F,3,FALSE),0),IFERROR(VLOOKUP("かぼちゃ",サイドマスタ!$A:$F,4,FALSE),0))*IFERROR(VLOOKUP("かぼちゃ",サイドマスタ!$A:$F,5,FALSE),0),0)+IFERROR(N13*IF($C13="黒弁当",IFERROR(VLOOKUP("小エビ",サイドマスタ!$A:$F,3,FALSE),0),IFERROR(VLOOKUP("小エビ",サイドマスタ!$A:$F,4,FALSE),0))*IFERROR(VLOOKUP("小エビ",サイドマスタ!$A:$F,5,FALSE),0),0)+IFERROR(O13*IF($C13="黒弁当",IFERROR(VLOOKUP("有頭エビ",サイドマスタ!$A:$F,3,FALSE),0),IFERROR(VLOOKUP("有頭エビ",サイドマスタ!$A:$F,4,FALSE),0))*IFERROR(VLOOKUP("有頭エビ",サイドマスタ!$A:$F,5,FALSE),0),0)+IFERROR(IF($C13="黒弁当",IFERROR(VLOOKUP("サラダベース",サイドマスタ!$A:$F,3,FALSE),0),IFERROR(VLOOKUP("サラダベース",サイドマスタ!$A:$F,4,FALSE),0))*IFERROR(VLOOKUP("サラダベース",サイドマスタ!$A:$F,5,FALSE),0),0)+IFERROR(IF($C13="黒弁当",IFERROR(VLOOKUP("ミニトマト",サイドマスタ!$A:$F,3,FALSE),0),IFERROR(VLOOKUP("ミニトマト",サイドマスタ!$A:$F,4,FALSE),0))*IFERROR(VLOOKUP("ミニトマト",サイドマスタ!$A:$F,5,FALSE),0),0)+IFERROR(IF($C13="黒弁当",IFERROR(VLOOKUP("蒸し野菜",サイドマスタ!$A:$F,3,FALSE),0),IFERROR(VLOOKUP("蒸し野菜",サイドマスタ!$A:$F,4,FALSE),0))*IFERROR(VLOOKUP("蒸し野菜",サイドマスタ!$A:$F,5,FALSE),0),0)+IFERROR(IF($C13="黒弁当",IFERROR(VLOOKUP("ブロッコリー",サイドマスタ!$A:$F,3,FALSE),0),IFERROR(VLOOKUP("ブロッコリー",サイドマスタ!$A:$F,4,FALSE),0))*IFERROR(VLOOKUP("ブロッコリー",サイドマスタ!$A:$F,5,FALSE),0),0) | W13: =IF(C13="黒弁当",IFERROR(VLOOKUP("容器（黒）",資材マスタ!$A$2:$C$10,3,FALSE),0)+IFERROR(VLOOKUP("蓋（黒）",資材マスタ!$A$2:$C$10,3,FALSE),0),IFERROR(VLOOKUP("容器（新）",資材マスタ!$A$2:$C$10,3,FALSE),0)+IFERROR(VLOOKUP("蓋（新）",資材マスタ!$A$2:$C$10,3,FALSE),0))+IFERROR(VLOOKUP("箸",資材マスタ!$A$2:$C$10,3,FALSE),0)+IFERROR(VLOOKUP("ワサガード",資材マスタ!$A$2:$C$10,3,FALSE),0)+IFERROR(VLOOKUP("帯",資材マスタ!$A$2:$C$10,3,FALSE),0)+IFERROR(VLOOKUP("シーザードレッシング",資材マスタ!$A$2:$C$10,3,FALSE),0)+IFERROR(VLOOKUP("おしぼり",資材マスタ!$A$2:$C$10,3,FALSE),0) | X13: =IFERROR(VLOOKUP(Q13,ソース定義マスタ!$A$2:$E$12,5,FALSE)*R13,0)+IFERROR(VLOOKUP(S13,ソース定義マスタ!$A$2:$E$12,5,FALSE)*T13,0) | Y13: =IFERROR(VLOOKUP(P13,飲料マスタ!$A$2:$D$5,4,FALSE),0) | Z13: =U13+V13+W13+X13+Y13 | AA13: =D13/1.08 | AB13: =IFERROR(Z13/AA13,0) | AC13: =IFERROR(1-AB13,0)
A14: 13 | B14: 特選ハラミのステーキとローストビーフ弁当 | C14: 新弁当 | D14: 2100 | E14: ハラミ | F14: 52 | G14: ロービー | H14: 42 | I14: 1 | J14: 1 | K14: 1 | L14: 1 | M14: 0 | N14: 0 | O14: 0 | P14: none | Q14: オニオンソース | R14: 20 | S14: エバラおろしのたれ | T14: 20 | U14: =IFERROR(VLOOKUP(E14,食材マスタ!$A$2:$F$17,6,FALSE)*F14,0)+IFERROR(VLOOKUP(G14,食材マスタ!$A$2:$F$17,6,FALSE)*H14,0) | V14: =IFERROR(I14*IF($C14="黒弁当",IFERROR(VLOOKUP("ピクルス",サイドマスタ!$A:$F,3,FALSE),0),IFERROR(VLOOKUP("ピクルス",サイドマスタ!$A:$F,4,FALSE),0))*IFERROR(VLOOKUP("ピクルス",サイドマスタ!$A:$F,5,FALSE),0),0)+IFERROR(J14*IF($C14="黒弁当",IFERROR(VLOOKUP("ポテトサラダ",サイドマスタ!$A:$F,3,FALSE),0),IFERROR(VLOOKUP("ポテトサラダ",サイドマスタ!$A:$F,4,FALSE),0))*IFERROR(VLOOKUP("ポテトサラダ",サイドマスタ!$A:$F,5,FALSE),0),0)+IFERROR(K14*IF($C14="黒弁当",IFERROR(VLOOKUP("卵",サイドマスタ!$A:$F,3,FALSE),0),IFERROR(VLOOKUP("卵",サイドマスタ!$A:$F,4,FALSE),0))*IFERROR(VLOOKUP("卵",サイドマスタ!$A:$F,5,FALSE),0),0)+IFERROR(L14*IF($C14="黒弁当",IFERROR(VLOOKUP("ご飯",サイドマスタ!$A:$F,3,FALSE),0),IFERROR(VLOOKUP("ご飯",サイドマスタ!$A:$F,4,FALSE),0))*IFERROR(VLOOKUP("ご飯",サイドマスタ!$A:$F,5,FALSE),0),0)+IFERROR(M14*IF($C14="黒弁当",IFERROR(VLOOKUP("かぼちゃ",サイドマスタ!$A:$F,3,FALSE),0),IFERROR(VLOOKUP("かぼちゃ",サイドマスタ!$A:$F,4,FALSE),0))*IFERROR(VLOOKUP("かぼちゃ",サイドマスタ!$A:$F,5,FALSE),0),0)+IFERROR(N14*IF($C14="黒弁当",IFERROR(VLOOKUP("小エビ",サイドマスタ!$A:$F,3,FALSE),0),IFERROR(VLOOKUP("小エビ",サイドマスタ!$A:$F,4,FALSE),0))*IFERROR(VLOOKUP("小エビ",サイドマスタ!$A:$F,5,FALSE),0),0)+IFERROR(O14*IF($C14="黒弁当",IFERROR(VLOOKUP("有頭エビ",サイドマスタ!$A:$F,3,FALSE),0),IFERROR(VLOOKUP("有頭エビ",サイドマスタ!$A:$F,4,FALSE),0))*IFERROR(VLOOKUP("有頭エビ",サイドマスタ!$A:$F,5,FALSE),0),0)+IFERROR(IF($C14="黒弁当",IFERROR(VLOOKUP("サラダベース",サイドマスタ!$A:$F,3,FALSE),0),IFERROR(VLOOKUP("サラダベース",サイドマスタ!$A:$F,4,FALSE),0))*IFERROR(VLOOKUP("サラダベース",サイドマスタ!$A:$F,5,FALSE),0),0)+IFERROR(IF($C14="黒弁当",IFERROR(VLOOKUP("ミニトマト",サイドマスタ!$A:$F,3,FALSE),0),IFERROR(VLOOKUP("ミニトマト",サイドマスタ!$A:$F,4,FALSE),0))*IFERROR(VLOOKUP("ミニトマト",サイドマスタ!$A:$F,5,FALSE),0),0)+IFERROR(IF($C14="黒弁当",IFERROR(VLOOKUP("蒸し野菜",サイドマスタ!$A:$F,3,FALSE),0),IFERROR(VLOOKUP("蒸し野菜",サイドマスタ!$A:$F,4,FALSE),0))*IFERROR(VLOOKUP("蒸し野菜",サイドマスタ!$A:$F,5,FALSE),0),0)+IFERROR(IF($C14="黒弁当",IFERROR(VLOOKUP("ブロッコリー",サイドマスタ!$A:$F,3,FALSE),0),IFERROR(VLOOKUP("ブロッコリー",サイドマスタ!$A:$F,4,FALSE),0))*IFERROR(VLOOKUP("ブロッコリー",サイドマスタ!$A:$F,5,FALSE),0),0) | W14: =IF(C14="黒弁当",IFERROR(VLOOKUP("容器（黒）",資材マスタ!$A$2:$C$10,3,FALSE),0)+IFERROR(VLOOKUP("蓋（黒）",資材マスタ!$A$2:$C$10,3,FALSE),0),IFERROR(VLOOKUP("容器（新）",資材マスタ!$A$2:$C$10,3,FALSE),0)+IFERROR(VLOOKUP("蓋（新）",資材マスタ!$A$2:$C$10,3,FALSE),0))+IFERROR(VLOOKUP("箸",資材マスタ!$A$2:$C$10,3,FALSE),0)+IFERROR(VLOOKUP("ワサガード",資材マスタ!$A$2:$C$10,3,FALSE),0)+IFERROR(VLOOKUP("帯",資材マスタ!$A$2:$C$10,3,FALSE),0)+IFERROR(VLOOKUP("シーザードレッシング",資材マスタ!$A$2:$C$10,3,FALSE),0)+IFERROR(VLOOKUP("おしぼり",資材マスタ!$A$2:$C$10,3,FALSE),0) | X14: =IFERROR(VLOOKUP(Q14,ソース定義マスタ!$A$2:$E$12,5,FALSE)*R14,0)+IFERROR(VLOOKUP(S14,ソース定義マスタ!$A$2:$E$12,5,FALSE)*T14,0) | Y14: =IFERROR(VLOOKUP(P14,飲料マスタ!$A$2:$D$5,4,FALSE),0) | Z14: =U14+V14+W14+X14+Y14 | AA14: =D14/1.08 | AB14: =IFERROR(Z14/AA14,0) | AC14: =IFERROR(1-AB14,0)
